Workbook

Sheet Sheet1
B25: क्र0 सं0 | C25: जनपद | D25: शॉर्ट सर्किट | E25: गैस लीकेज | F25: ओवर हीटिंग | G25: आतिशबाजी | H25: नरई जलाने से | I25: धूम्रपान | J25: लापरवाही | K25: जान-बूझकर | L25: अज्ञात | M25: कारण अंकित नहीं है | N25: जंगल | O25: कुल
B26: 1 | C26: अल्मोड़ा | D26: =COUNTIFS(Table1[जनपद],Table2[[#This Row],[जनपद]],Table1[कारण],Table2[[#Headers],[शॉर्ट सर्किट]]) -> 0 | E26: =COUNTIFS(Table1[जनपद],Table2[[#This Row],[जनपद]],Table1[कारण],Table2[[#Headers],[गैस लीकेज]]) -> 0 | F26: =COUNTIFS(Table1[जनपद],Table2[[#This Row],[जनपद]],Table1[कारण],Table2[[#Headers],[ओवर हीटिंग]]) -> 0 | G26: =COUNTIFS(Table1[जनपद],Table2[[#This Row],[जनपद]],Table1[कारण],Table2[[#Headers],[आतिशबाजी]]) -> 0 | H26: =COUNTIFS(Table1[जनपद],Table2[[#This Row],[जनपद]],Table1[कारण],Table2[[#Headers],[नरई जलाने से]]) -> 0 | I26: =COUNTIFS(Table1[जनपद],Table2[[#This Row],[जनपद]],Table1[कारण],Table2[[#Headers],[धूम्रपान]]) -> 0 | J26: =COUNTIFS(Table1[जनपद],Table2[[#This Row],[जनपद]],Table1[कारण],Table2[[#Headers],[लापरवाही]]) -> 0 | K26: =COUNTIFS(Table1[जनपद],Table2[[#This Row],[जनपद]],Table1[कारण],Table2[[#Headers],[जान-बूझकर]]) -> 0 | L26: =COUNTIFS(Table1[जनपद],Table2[[#This Row],[जनपद]],Table1[कारण],Table2[[#Headers],[अज्ञात]]) -> 0 | M26: =COUNTIFS(Table1[जनपद],Table2[[#This Row],[जनपद]],Table1[कारण],"") -> 0 | N26: =COUNTIFS(Table1[जनपद],Table2[[#This Row],[जनपद]],Table1[कारण],Table2[[#Headers],[जंगल]]) -> 0 | O26: =SUM(Table2[[#This Row],[शॉर्ट सर्किट]:[कारण अंकित नहीं है]]) -> 0 | R26: शॉर्ट सर्किट | S26: =Table2[[#Totals],[शॉर्ट सर्किट]] -> 71
B27: 2 | C27: बागेश्वर | D27: =COUNTIFS(Table1[जनपद],Table2[[#This Row],[जनपद]],Table1[कारण],Table2[[#Headers],[शॉर्ट सर्किट]]) -> 0 | E27: =COUNTIFS(Table1[जनपद],Table2[[#This Row],[जनपद]],Table1[कारण],Table2[[#Headers],[गैस लीकेज]]) -> 0 | F27: =COUNTIFS(Table1[जनपद],Table2[[#This Row],[जनपद]],Table1[कारण],Table2[[#Headers],[ओवर हीटिंग]]) -> 0 | G27: =COUNTIFS(Table1[जनपद],Table2[[#This Row],[जनपद]],Table1[कारण],Table2[[#Headers],[आतिशबाजी]]) -> 0 | H27: =COUNTIFS(Table1[जनपद],Table2[[#This Row],[जनपद]],Table1[कारण],Table2[[#Headers],[नरई जलाने से]]) -> 0 | I27: =COUNTIFS(Table1[जनपद],Table2[[#This Row],[जनपद]],Table1[कारण],Table2[[#Headers],[धूम्रपान]]) -> 0 | J27: =COUNTIFS(Table1[जनपद],Table2[[#This Row],[जनपद]],Table1[कारण],Table2[[#Headers],[लापरवाही]]) -> 0 | K27: =COUNTIFS(Table1[जनपद],Table2[[#This Row],[जनपद]],Table1[कारण],Table2[[#Headers],[जान-बूझकर]]) -> 0 | L27: =COUNTIFS(Table1[जनपद],Table2[[#This Row],[जनपद]],Table1[कारण],Table2[[#Headers],[अज्ञात]]) -> 0 | M27: =COUNTIFS(Table1[जनपद],Table2[[#This Row],[जनपद]],Table1[कारण],"") -> 22 | N27: =COUNTIFS(Table1[जनपद],Table2[[#This Row],[जनपद]],Table1[कारण],Table2[[#Headers],[जंगल]]) -> 0 | O27: =SUM(Table2[[#This Row],[शॉर्ट सर्किट]:[कारण अंकित नहीं है]]) -> 22 | R27: गैस लीकेज | S27: =Table2[[#Totals],[गैस लीकेज]] -> 8
B28: 3 | C28: चमोली | D28: =COUNTIFS(Table1[जनपद],Table2[[#This Row],[जनपद]],Table1[कारण],Table2[[#Headers],[शॉर्ट सर्किट]]) -> 1 | E28: =COUNTIFS(Table1[जनपद],Table2[[#This Row],[जनपद]],Table1[कारण],Table2[[#Headers],[गैस लीकेज]]) -> 0 | F28: =COUNTIFS(Table1[जनपद],Table2[[#This Row],[जनपद]],Table1[कारण],Table2[[#Headers],[ओवर हीटिंग]]) -> 0 | G28: =COUNTIFS(Table1[जनपद],Table2[[#This Row],[जनपद]],Table1[कारण],Table2[[#Headers],[आतिशबाजी]]) -> 0 | H28: =COUNTIFS(Table1[जनपद],Table2[[#This Row],[जनपद]],Table1[कारण],Table2[[#Headers],[नरई जलाने से]]) -> 0 | I28: =COUNTIFS(Table1[जनपद],Table2[[#This Row],[जनपद]],Table1[कारण],Table2[[#Headers],[धूम्रपान]]) -> 0 | J28: =COUNTIFS(Table1[जनपद],Table2[[#This Row],[जनपद]],Table1[कारण],Table2[[#Headers],[लापरवाही]]) -> 0 | K28: =COUNTIFS(Table1[जनपद],Table2[[#This Row],[जनपद]],Table1[कारण],Table2[[#Headers],[जान-बूझकर]]) -> 0 | L28: =COUNTIFS(Table1[जनपद],Table2[[#This Row],[जनपद]],Table1[कारण],Table2[[#Headers],[अज्ञात]]) -> 3 | M28: =COUNTIFS(Table1[जनपद],Table2[[#This Row],[जनपद]],Table1[कारण],"") -> 10 | N28: =COUNTIFS(Table1[जनपद],Table2[[#This Row],[जनपद]],Table1[कारण],Table2[[#Headers],[जंगल]]) -> 0 | O28: =SUM(Table2[[#This Row],[शॉर्ट सर्किट]:[कारण अंकित नहीं है]]) -> 14 | R28: ओवर हीटिंग | S28: =Table2[[#Totals],[ओवर हीटिंग]] -> 2
B29: 4 | C29: चम्पावत | D29: =COUNTIFS(Table1[जनपद],Table2[[#This Row],[जनपद]],Table1[कारण],Table2[[#Headers],[शॉर्ट सर्किट]]) -> 0 | E29: =COUNTIFS(Table1[जनपद],Table2[[#This Row],[जनपद]],Table1[कारण],Table2[[#Headers],[गैस लीकेज]]) -> 0 | F29: =COUNTIFS(Table1[जनपद],Table2[[#This Row],[जनपद]],Table1[कारण],Table2[[#Headers],[ओवर हीटिंग]]) -> 0 | G29: =COUNTIFS(Table1[जनपद],Table2[[#This Row],[जनपद]],Table1[कारण],Table2[[#Headers],[आतिशबाजी]]) -> 0 | H29: =COUNTIFS(Table1[जनपद],Table2[[#This Row],[जनपद]],Table1[कारण],Table2[[#Headers],[नरई जलाने से]]) -> 0 | I29: =COUNTIFS(Table1[जनपद],Table2[[#This Row],[जनपद]],Table1[कारण],Table2[[#Headers],[धूम्रपान]]) -> 0 | J29: =COUNTIFS(Table1[जनपद],Table2[[#This Row],[जनपद]],Table1[कारण],Table2[[#Headers],[लापरवाही]]) -> 0 | K29: =COUNTIFS(Table1[जनपद],Table2[[#This Row],[जनपद]],Table1[कारण],Table2[[#Headers],[जान-बूझकर]]) -> 0 | L29: =COUNTIFS(Table1[जनपद],Table2[[#This Row],[जनपद]],Table1[कारण],Table2[[#Headers],[अज्ञात]]) -> 0 | M29: =COUNTIFS(Table1[जनपद],Table2[[#This Row],[जनपद]],Table1[कारण],"") -> 0 | N29: =COUNTIFS(Table1[जनपद],Table2[[#This Row],[जनपद]],Table1[कारण],Table2[[#Headers],[जंगल]]) -> 0 | O29: =SUM(Table2[[#This Row],[शॉर्ट सर्किट]:[कारण अंकित नहीं है]]) -> 0 | R29: आतिशबाजी | S29: =Table2[[#Totals],[आतिशबाजी]] -> 1
B30: 5 | C30: देहरादून | D30: =COUNTIFS(Table1[जनपद],Table2[[#This Row],[जनपद]],Table1[कारण],Table2[[#Headers],[शॉर्ट सर्किट]]) -> 39 | E30: =COUNTIFS(Table1[जनपद],Table2[[#This Row],[जनपद]],Table1[कारण],Table2[[#Headers],[गैस लीकेज]]) -> 3 | F30: =COUNTIFS(Table1[जनपद],Table2[[#This Row],[जनपद]],Table1[कारण],Table2[[#Headers],[ओवर हीटिंग]]) -> 0 | G30: =COUNTIFS(Table1[जनपद],Table2[[#This Row],[जनपद]],Table1[कारण],Table2[[#Headers],[आतिशबाजी]]) -> 0 | H30: =COUNTIFS(Table1[जनपद],Table2[[#This Row],[जनपद]],Table1[कारण],Table2[[#Headers],[नरई जलाने से]]) -> 0 | I30: =COUNTIFS(Table1[जनपद],Table2[[#This Row],[जनपद]],Table1[कारण],Table2[[#Headers],[धूम्रपान]]) -> 14 | J30: =COUNTIFS(Table1[जनपद],Table2[[#This Row],[जनपद]],Table1[कारण],Table2[[#Headers],[लापरवाही]]) -> 58 | K30: =COUNTIFS(Table1[जनपद],Table2[[#This Row],[जनपद]],Table1[कारण],Table2[[#Headers],[जान-बूझकर]]) -> 0 | L30: =COUNTIFS(Table1[जनपद],Table2[[#This Row],[जनपद]],Table1[कारण],Table2[[#Headers],[अज्ञात]]) -> 10 | M30: =COUNTIFS(Table1[जनपद],Table2[[#This Row],[जनपद]],Table1[कारण],"") -> 19 | N30: =COUNTIFS(Table1[जनपद],Table2[[#This Row],[जनपद]],Table1[कारण],Table2[[#Headers],[जंगल]]) -> 7 | O30: =SUM(Table2[[#This Row],[शॉर्ट सर्किट]:[कारण अंकित नहीं है]]) -> 143 | R30: नरई जलाने से | S30: =Table2[[#Totals],[नरई जलाने से]] -> 0
B31: 6 | C31: हरिद्वार | D31: =COUNTIFS(Table1[जनपद],Table2[[#This Row],[जनपद]],Table1[कारण],Table2[[#Headers],[शॉर्ट सर्किट]]) -> 16 | E31: =COUNTIFS(Table1[जनपद],Table2[[#This Row],[जनपद]],Table1[कारण],Table2[[#Headers],[गैस लीकेज]]) -> 2 | F31: =COUNTIFS(Table1[जनपद],Table2[[#This Row],[जनपद]],Table1[कारण],Table2[[#Headers],[ओवर हीटिंग]]) -> 0 | G31: =COUNTIFS(Table1[जनपद],Table2[[#This Row],[जनपद]],Table1[कारण],Table2[[#Headers],[आतिशबाजी]]) -> 0 | H31: =COUNTIFS(Table1[जनपद],Table2[[#This Row],[जनपद]],Table1[कारण],Table2[[#Headers],[नरई जलाने से]]) -> 0 | I31: =COUNTIFS(Table1[जनपद],Table2[[#This Row],[जनपद]],Table1[कारण],Table2[[#Headers],[धूम्रपान]]) -> 38 | J31: =COUNTIFS(Table1[जनपद],Table2[[#This Row],[जनपद]],Table1[कारण],Table2[[#Headers],[लापरवाही]]) -> 0 | K31: =COUNTIFS(Table1[जनपद],Table2[[#This Row],[जनपद]],Table1[कारण],Table2[[#Headers],[जान-बूझकर]]) -> 0 | L31: =COUNTIFS(Table1[जनपद],Table2[[#This Row],[जनपद]],Table1[कारण],Table2[[#Headers],[अज्ञात]]) -> 13 | M31: =COUNTIFS(Table1[जनपद],Table2[[#This Row],[जनपद]],Table1[कारण],"") -> 11 | N31: =COUNTIFS(Table1[जनपद],Table2[[#This Row],[जनपद]],Table1[कारण],Table2[[#Headers],[जंगल]]) -> 0 | O31: =SUM(Table2[[#This Row],[शॉर्ट सर्किट]:[कारण अंकित नहीं है]]) -> 80 | R31: धूम्रपान | S31: =Table2[[#Totals],[धूम्रपान]] -> 88
B32: 7 | C32: नैनीताल | D32: =COUNTIFS(Table1[जनपद],Table2[[#This Row],[जनपद]],Table1[कारण],Table2[[#Headers],[शॉर्ट सर्किट]]) -> 0 | E32: =COUNTIFS(Table1[जनपद],Table2[[#This Row],[जनपद]],Table1[कारण],Table2[[#Headers],[गैस लीकेज]]) -> 0 | F32: =COUNTIFS(Table1[जनपद],Table2[[#This Row],[जनपद]],Table1[कारण],Table2[[#Headers],[ओवर हीटिंग]]) -> 0 | G32: =COUNTIFS(Table1[जनपद],Table2[[#This Row],[जनपद]],Table1[कारण],Table2[[#Headers],[आतिशबाजी]]) -> 0 | H32: =COUNTIFS(Table1[जनपद],Table2[[#This Row],[जनपद]],Table1[कारण],Table2[[#Headers],[नरई जलाने से]]) -> 0 | I32: =COUNTIFS(Table1[जनपद],Table2[[#This Row],[जनपद]],Table1[कारण],Table2[[#Headers],[धूम्रपान]]) -> 0 | J32: =COUNTIFS(Table1[जनपद],Table2[[#This Row],[जनपद]],Table1[कारण],Table2[[#Headers],[लापरवाही]]) -> 0 | K32: =COUNTIFS(Table1[जनपद],Table2[[#This Row],[जनपद]],Table1[कारण],Table2[[#Headers],[जान-बूझकर]]) -> 0 | L32: =COUNTIFS(Table1[जनपद],Table2[[#This Row],[जनपद]],Table1[कारण],Table2[[#Headers],[अज्ञात]]) -> 0 | M32: =COUNTIFS(Table1[जनपद],Table2[[#This Row],[जनपद]],Table1[कारण],"") -> 0 | N32: =COUNTIFS(Table1[जनपद],Table2[[#This Row],[जनपद]],Table1[कारण],Table2[[#Headers],[जंगल]]) -> 0 | O32: =SUM(Table2[[#This Row],[शॉर्ट सर्किट]:[कारण अंकित नहीं है]]) -> 0 | R32: लापरवाही | S32: =Table2[[#Totals],[लापरवाही]] -> 58
B33: 8 | C33: पौड़ी | D33: =COUNTIFS(Table1[जनपद],Table2[[#This Row],[जनपद]],Table1[कारण],Table2[[#Headers],[शॉर्ट सर्किट]]) -> 0 | E33: =COUNTIFS(Table1[जनपद],Table2[[#This Row],[जनपद]],Table1[कारण],Table2[[#Headers],[गैस लीकेज]]) -> 0 | F33: =COUNTIFS(Table1[जनपद],Table2[[#This Row],[जनपद]],Table1[कारण],Table2[[#Headers],[ओवर हीटिंग]]) -> 0 | G33: =COUNTIFS(Table1[जनपद],Table2[[#This Row],[जनपद]],Table1[कारण],Table2[[#Headers],[आतिशबाजी]]) -> 0 | H33: =COUNTIFS(Table1[जनपद],Table2[[#This Row],[जनपद]],Table1[कारण],Table2[[#Headers],[नरई जलाने से]]) -> 0 | I33: =COUNTIFS(Table1[जनपद],Table2[[#This Row],[जनपद]],Table1[कारण],Table2[[#Headers],[धूम्रपान]]) -> 0 | J33: =COUNTIFS(Table1[जनपद],Table2[[#This Row],[जनपद]],Table1[कारण],Table2[[#Headers],[लापरवाही]]) -> 0 | K33: =COUNTIFS(Table1[जनपद],Table2[[#This Row],[जनपद]],Table1[कारण],Table2[[#Headers],[जान-बूझकर]]) -> 0 | L33: =COUNTIFS(Table1[जनपद],Table2[[#This Row],[जनपद]],Table1[कारण],Table2[[#Headers],[अज्ञात]]) -> 0 | M33: =COUNTIFS(Table1[जनपद],Table2[[#This Row],[जनपद]],Table1[कारण],"") -> 0 | N33: =COUNTIFS(Table1[जनपद],Table2[[#This Row],[जनपद]],Table1[कारण],Table2[[#Headers],[जंगल]]) -> 0 | O33: =SUM(Table2[[#This Row],[शॉर्ट सर्किट]:[कारण अंकित नहीं है]]) -> 0 | R33: जान-बूझकर | S33: =Table2[[#Totals],[जान-बूझकर]] -> 0
B34: 9 | C34: पिथौरागढ़ | D34: =COUNTIFS(Table1[जनपद],Table2[[#This Row],[जनपद]],Table1[कारण],Table2[[#Headers],[शॉर्ट सर्किट]]) -> 0 | E34: =COUNTIFS(Table1[जनपद],Table2[[#This Row],[जनपद]],Table1[कारण],Table2[[#Headers],[गैस लीकेज]]) -> 0 | F34: =COUNTIFS(Table1[जनपद],Table2[[#This Row],[जनपद]],Table1[कारण],Table2[[#Headers],[ओवर हीटिंग]]) -> 0 | G34: =COUNTIFS(Table1[जनपद],Table2[[#This Row],[जनपद]],Table1[कारण],Table2[[#Headers],[आतिशबाजी]]) -> 0 | H34: =COUNTIFS(Table1[जनपद],Table2[[#This Row],[जनपद]],Table1[कारण],Table2[[#Headers],[नरई जलाने से]]) -> 0 | I34: =COUNTIFS(Table1[जनपद],Table2[[#This Row],[जनपद]],Table1[कारण],Table2[[#Headers],[धूम्रपान]]) -> 0 | J34: =COUNTIFS(Table1[जनपद],Table2[[#This Row],[जनपद]],Table1[कारण],Table2[[#Headers],[लापरवाही]]) -> 0 | K34: =COUNTIFS(Table1[जनपद],Table2[[#This Row],[जनपद]],Table1[कारण],Table2[[#Headers],[जान-बूझकर]]) -> 0 | L34: =COUNTIFS(Table1[जनपद],Table2[[#This Row],[जनपद]],Table1[कारण],Table2[[#Headers],[अज्ञात]]) -> 0 | M34: =COUNTIFS(Table1[जनपद],Table2[[#This Row],[जनपद]],Table1[कारण],"") -> 0 | N34: =COUNTIFS(Table1[जनपद],Table2[[#This Row],[जनपद]],Table1[कारण],Table2[[#Headers],[जंगल]]) -> 0 | O34: =SUM(Table2[[#This Row],[शॉर्ट सर्किट]:[कारण अंकित नहीं है]]) -> 0 | R34: अज्ञात | S34: =Table2[[#Totals],[अज्ञात]] -> 31
B35: 10 | C35: रुद्रप्रयाग | D35: =COUNTIFS(Table1[जनपद],Table2[[#This Row],[जनपद]],Table1[कारण],Table2[[#Headers],[शॉर्ट सर्किट]]) -> 0 | E35: =COUNTIFS(Table1[जनपद],Table2[[#This Row],[जनपद]],Table1[कारण],Table2[[#Headers],[गैस लीकेज]]) -> 0 | F35: =COUNTIFS(Table1[जनपद],Table2[[#This Row],[जनपद]],Table1[कारण],Table2[[#Headers],[ओवर हीटिंग]]) -> 0 | G35: =COUNTIFS(Table1[जनपद],Table2[[#This Row],[जनपद]],Table1[कारण],Table2[[#Headers],[आतिशबाजी]]) -> 0 | H35: =COUNTIFS(Table1[जनपद],Table2[[#This Row],[जनपद]],Table1[कारण],Table2[[#Headers],[नरई जलाने से]]) -> 0 | I35: =COUNTIFS(Table1[जनपद],Table2[[#This Row],[जनपद]],Table1[कारण],Table2[[#Headers],[धूम्रपान]]) -> 0 | J35: =COUNTIFS(Table1[जनपद],Table2[[#This Row],[जनपद]],Table1[कारण],Table2[[#Headers],[लापरवाही]]) -> 0 | K35: =COUNTIFS(Table1[जनपद],Table2[[#This Row],[जनपद]],Table1[कारण],Table2[[#Headers],[जान-बूझकर]]) -> 0 | L35: =COUNTIFS(Table1[जनपद],Table2[[#This Row],[जनपद]],Table1[कारण],Table2[[#Headers],[अज्ञात]]) -> 0 | M35: =COUNTIFS(Table1[जनपद],Table2[[#This Row],[जनपद]],Table1[कारण],"") -> 0 | N35: =COUNTIFS(Table1[जनपद],Table2[[#This Row],[जनपद]],Table1[कारण],Table2[[#Headers],[जंगल]]) -> 0 | O35: =SUM(Table2[[#This Row],[शॉर्ट सर्किट]:[कारण अंकित नहीं है]]) -> 0 | R35: कारण अंकित नहीं है | S35: =Table2[[#Totals],[कारण अंकित नहीं है]] -> 105
B36: 11 | C36: टिहरी | D36: =COUNTIFS(Table1[जनपद],Table2[[#This Row],[जनपद]],Table1[कारण],Table2[[#Headers],[शॉर्ट सर्किट]]) -> 0 | E36: =COUNTIFS(Table1[जनपद],Table2[[#This Row],[जनपद]],Table1[कारण],Table2[[#Headers],[गैस लीकेज]]) -> 0 | F36: =COUNTIFS(Table1[जनपद],Table2[[#This Row],[जनपद]],Table1[कारण],Table2[[#Headers],[ओवर हीटिंग]]) -> 0 | G36: =COUNTIFS(Table1[जनपद],Table2[[#This Row],[जनपद]],Table1[कारण],Table2[[#Headers],[आतिशबाजी]]) -> 0 | H36: =COUNTIFS(Table1[जनपद],Table2[[#This Row],[जनपद]],Table1[कारण],Table2[[#Headers],[नरई जलाने से]]) -> 0 | I36: =COUNTIFS(Table1[जनपद],Table2[[#This Row],[जनपद]],Table1[कारण],Table2[[#Headers],[धूम्रपान]]) -> 0 | J36: =COUNTIFS(Table1[जनपद],Table2[[#This Row],[जनपद]],Table1[कारण],Table2[[#Headers],[लापरवाही]]) -> 0 | K36: =COUNTIFS(Table1[जनपद],Table2[[#This Row],[जनपद]],Table1[कारण],Table2[[#Headers],[जान-बूझकर]]) -> 0 | L36: =COUNTIFS(Table1[जनपद],Table2[[#This Row],[जनपद]],Table1[कारण],Table2[[#Headers],[अज्ञात]]) -> 0 | M36: =COUNTIFS(Table1[जनपद],Table2[[#This Row],[जनपद]],Table1[कारण],"") -> 0 | N36: =COUNTIFS(Table1[जनपद],Table2[[#This Row],[जनपद]],Table1[कारण],Table2[[#Headers],[जंगल]]) -> 0 | O36: =SUM(Table2[[#This Row],[शॉर्ट सर्किट]:[कारण अंकित नहीं है]]) -> 0 | R36: फोरेस्ट फायर | S36: =Table2[[#Totals],[जंगल]] -> 470
B37: 12 | C37: ऊधमसिंहनगर | D37: =COUNTIFS(Table1[जनपद],Table2[[#This Row],[जनपद]],Table1[कारण],Table2[[#Headers],[शॉर्ट सर्किट]]) -> 15 | E37: =COUNTIFS(Table1[जनपद],Table2[[#This Row],[जनपद]],Table1[कारण],Table2[[#Headers],[गैस लीकेज]]) -> 3 | F37: =COUNTIFS(Table1[जनपद],Table2[[#This Row],[जनपद]],Table1[कारण],Table2[[#Headers],[ओवर हीटिंग]]) -> 2 | G37: =COUNTIFS(Table1[जनपद],Table2[[#This Row],[जनपद]],Table1[कारण],Table2[[#Headers],[आतिशबाजी]]) -> 1 | H37: =COUNTIFS(Table1[जनपद],Table2[[#This Row],[जनपद]],Table1[कारण],Table2[[#Headers],[नरई जलाने से]]) -> 0 | I37: =COUNTIFS(Table1[जनपद],Table2[[#This Row],[जनपद]],Table1[कारण],Table2[[#Headers],[धूम्रपान]]) -> 35 | J37: =COUNTIFS(Table1[जनपद],Table2[[#This Row],[जनपद]],Table1[कारण],Table2[[#Headers],[लापरवाही]]) -> 0 | K37: =COUNTIFS(Table1[जनपद],Table2[[#This Row],[जनपद]],Table1[कारण],Table2[[#Headers],[जान-बूझकर]]) -> 0 | L37: =COUNTIFS(Table1[जनपद],Table2[[#This Row],[जनपद]],Table1[कारण],Table2[[#Headers],[अज्ञात]]) -> 5 | M37: =COUNTIFS(Table1[जनपद],Table2[[#This Row],[जनपद]],Table1[कारण],"") -> 8 | N37: =COUNTIFS(Table1[जनपद],Table2[[#This Row],[जनपद]],Table1[कारण],Table2[[#Headers],[जंगल]]) -> 1 | O37: =SUM(Table2[[#This Row],[शॉर्ट सर्किट]:[कारण अंकित नहीं है]]) -> 69
B38: 13 | C38: उत्तरकाशी | D38: =COUNTIFS(Table1[जनपद],Table2[[#This Row],[जनपद]],Table1[कारण],Table2[[#Headers],[शॉर्ट सर्किट]]) -> 0 | E38: =COUNTIFS(Table1[जनपद],Table2[[#This Row],[जनपद]],Table1[कारण],Table2[[#Headers],[गैस लीकेज]]) -> 0 | F38: =COUNTIFS(Table1[जनपद],Table2[[#This Row],[जनपद]],Table1[कारण],Table2[[#Headers],[ओवर हीटिंग]]) -> 0 | G38: =COUNTIFS(Table1[जनपद],Table2[[#This Row],[जनपद]],Table1[कारण],Table2[[#Headers],[आतिशबाजी]]) -> 0 | H38: =COUNTIFS(Table1[जनपद],Table2[[#This Row],[जनपद]],Table1[कारण],Table2[[#Headers],[नरई जलाने से]]) -> 0 | I38: =COUNTIFS(Table1[जनपद],Table2[[#This Row],[जनपद]],Table1[कारण],Table2[[#Headers],[धूम्रपान]]) -> 1 | J38: =COUNTIFS(Table1[जनपद],Table2[[#This Row],[जनपद]],Table1[कारण],Table2[[#Headers],[लापरवाही]]) -> 0 | K38: =COUNTIFS(Table1[जनपद],Table2[[#This Row],[जनपद]],Table1[कारण],Table2[[#Headers],[जान-बूझकर]]) -> 0 | L38: =COUNTIFS(Table1[जनपद],Table2[[#This Row],[जनपद]],Table1[कारण],Table2[[#Headers],[अज्ञात]]) -> 0 | M38: =COUNTIFS(Table1[जनपद],Table2[[#This Row],[जनपद]],Table1[कारण],"") -> 35 | N38: 462 | O38: =SUM(Table2[[#This Row],[शॉर्ट सर्किट]:[कारण अंकित नहीं है]]) -> 36
B39: Total | D39: =SUBTOTAL(109,Table2[शॉर्ट सर्किट]) -> 71 | E39: =SUBTOTAL(109,Table2[गैस लीकेज]) -> 8 | F39: =SUBTOTAL(109,Table2[ओवर हीटिंग]) -> 2 | G39: =SUBTOTAL(109,Table2[आतिशबाजी]) -> 1 | H39: =SUBTOTAL(109,Table2[नरई जलाने से]) -> 0 | I39: =SUBTOTAL(109,Table2[धूम्रपान]) -> 88 | J39: =SUBTOTAL(109,Table2[लापरवाही]) -> 58 | K39: =SUBTOTAL(109,Table2[जान-बूझकर]) -> 0 | L39: =SUBTOTAL(109,Table2[अज्ञात]) -> 31 | M39: =SUBTOTAL(109,Table2[कारण अंकित नहीं है]) -> 105 | N39: =SUBTOTAL(109,Table2[जंगल]) -> 470 | O39: =SUBTOTAL(109,Table2[कुल]) -> 364
F44: Vehicle Fire | I44: Building Fire
E45: कार | F45: =COUNTIF(Table1[Goods],Sheet1!E45) -> 3 | G45: =F45/$F$53 -> 1 | I45: घर | J45: =COUNTIF(Table1[Goods],Sheet1!I45) -> 8 | K45: =J45/$J$53 -> 0.47058824
E46: बस | F46: =COUNTIF(Table1[Goods],Sheet1!E46) -> 0 | G46: =F46/$F$53 -> 0 | I46: दुकान | J46: =COUNTIF(Table1[Goods],Sheet1!I46) -> 2 | K46: =J46/$J$53 -> 0.11764706
E47: ट्रक | F47: =COUNTIF(Table1[Goods],Sheet1!E47) -> 0 | G47: =F47/$F$53 -> 0 | I47: फैक्ट्री | J47: =COUNTIF(Table1[Goods],Sheet1!I47) -> 1 | K47: =J47/$J$53 -> 0.058823529
E48: क्रैन | F48: =COUNTIF(Table1[Goods],Sheet1!E48) -> 0 | G48: =F48/$F$53 -> 0 | I48: फ्लैट | J48: =COUNTIF(Table1[Goods],Sheet1!I48) -> 0 | K48: =J48/$J$53 -> 0
E49: बाइक | F49: =COUNTIF(Table1[Goods],Sheet1!E49) -> 0 | G49: =F49/$F$53 -> 0 | I49: गोदाम | J49: =COUNTIF(Table1[Goods],Sheet1!I49) -> 3 | K49: =J49/$J$53 -> 0.17647059
E50: स्कूटी | F50: =COUNTIF(Table1[Goods],Sheet1!E50) -> 0 | G50: =F50/$F$53 -> 0 | I50: होटल | J50: =COUNTIF(Table1[Goods],Sheet1!I50) -> 0 | K50: =J50/$J$53 -> 0
E51: टैम्पो | F51: =COUNTIF(Table1[Goods],Sheet1!E51) -> 0 | G51: =F51/$F$53 -> 0 | I51: बैंक | J51: =COUNTIF(Table1[Goods],Sheet1!I51) -> 0 | K51: =J51/$J$53 -> 0
I52: झोपड़ी | J52: =COUNTIF(Table1[Goods],Sheet1!I52) -> 3 | K52: =J52/$J$53 -> 0.17647059
F53: =SUM(F45:F52) -> 3 | J53: =SUM(J45:J52) -> 17

Sheet All-Final
B2: क्र. | C2: क्र.2 | D2: जनपद | E2: (जिस फायर स्टेशन क्षेत्रार्न्तागत अग्निकाण्ड हुआ हो) | F2: अग्निकाण्ड का दिनांक | G2: समय | H2: घटनास्थल का संक्षेप्त विवरण | I2: अग्निकाण्ड का कारण | J2: कारण | K2: अग्निकाण्ड का प्रकार (आग किस वस्तु में लगी है) | L2: Goods | M2: अनुमानित क्षति सम्पति (फायर रिपोर्ट के आधार पर) | N2: अनुमानित बचायी गई सम्पति | O2: जीव मरे (मनुष्य) | P2: जीव मरे (पशु) | Q2: जीव घायल (मनुष्य) | R2: जीव घायल (पशु) | S2: जीव बचे (मनुष्य) | T2: जीव बचे (पशु)
B3: 2301 | C3: 24 | D3: उत्तरकाशी | E3: उत्तरकाशी | F3: 45444 | G3: 0.35416667 | H3: आग की सूचना प्राप्त होते ही फायर यूनिट घटना स्थल को रवाना हुए पहुचकर देखा कि आग मही डांडा प्ज्ठच् कैम्पस के चारो ओर जंगल में लगी थी, जो कि तेजी से ऑफिसर मैस एवं ऑफिसर कॉलानी की तरफ बढ रही थी। जिसे फायर यूनिट ने एम0एफ0ई0 से पम्पिंग कर 04 हौज फेलाकर आग को पूर्णरूप से बुझाया बाद अग्निशमन कार्य के फायर यूनिट जल संस्थान से वाहन में पानी भरकर वापस फायर स्टेशन उपस्थित हुए। | M3: 20000 | N3: 3480000 | O3: - | P3: - | Q3: - | R3: - | S3: - | T3: -
B4: 2302 | C4: 25 | D4: उत्तरकाशी | E4: उत्तरकाशी | F4: 45444 | G4: 0.68263889 | H4: आग की सूचना प्राप्त होते ही फायर यूनिट घटना स्थल को रवाना हुए पहुचकर देखा कि आग क्ळठत् कैम्प से ऊपर तेखला के समीप जंगल मे लगी थी जो कि तेजी से छप्ड प्रशिक्षण कन्द्र की ओर बढ रही थी। जिसे फायर यूनिट ने हाई प्रेशर पम्प से पम्पिंग कर होजरील की सहायता से आग को पूर्णरूप से बुझाया बाद अग्निशमन कार्य के फायर यूनिट जल संस्थान से वाहन में पानी भरकर वापस फायर स्टेशन उपस्थित हुए। | M4: 5000 | N4: 1995000 | O4: - | P4: - | Q4: - | R4: - | S4: - | T4: -
B5: 2303 | C5: 26 | D5: उत्तरकाशी | E5: उत्तरकाशी | F5: 45444 | G5: 0.68472222 | H5: आग की सूचना प्राप्त होते ही फायर यूनिट घटना स्थल को रवाना हुए पहुचकर देखा कि आग सिलक्यारा के पास जंगल में लगी थी जो तेजी से आवासीय कालोनी की ओर बढ रही थी जिसे फायर यूनिट ने एम0एफ0ई0 से पम्पिंग कर होजरील एव होज पाईप फैलाकरे आग को पूर्णरूप से बुझाया बाद अग्निशमन कार्य के फायर यूनिट धरासू पुल से पानी भर कर वापास एफएस यूनिट चिन्यालीसैड उपस्थित हुए। | M5: 5000 | N5: 1995000 | O5: - | P5: - | Q5: - | R5: - | S5: - | T5: -
B6: 2314 | C6: 37 | D6: उत्तरकाशी | E6: नौगांव (बडकोट) | F6: 45444 | G6: 0.43402778 | H6: स्टेशन प्रभारी महोदय के माबाईल पर ओरछा बैंड के निकट जंगल में आग लगने की सूचना प्राप्त हुई जो बडी तेजी से आवासीय बस्ती की और बढ रही है। उक्त सूचना पर त्वरित कार्यवाही करते हुयें फायर यूनिट बडकोट घटना स्थल हेतु रवना हुई तथा घटना स्थल पर पहुॅच कर मो0फ0ई0 से हौज रील फैलाकर आग को बुझाना आरम्भ किया गया एवं आग को आवासीय बस्ती की और आने से रोका गया तथा कडी महनत कर व लगातार पानी का छिडकाव कर आग को पूर्ण रूप से बुझा दिया गया। उक्त आग में स्थानिय लोगो के फल दार वृक्ष जल कर नष्ट हो गये अन्य किसी भी प्रकार की कोई जन हानि नही हुई है। | M6: 1,00,000/- | N6: 49,00,000/- | O6: - | P6: - | Q6: - | R6: - | S6: - | T6: -
B7: 2315 | C7: 38 | D7: उत्तरकाशी | E7: नौगांव (बडकोट) | F7: 45444 | G7: 0.49583333 | H7: एम.डी.टी. पर तिलाडी रोड बडकोट में जंगल में आग लगने की सूचना प्राप्त हुई सूचना प्रात्प होते ही फायर यूनिट बडकोट घटना स्थल पर पहुॅची तथा देखा की आग डम्पिंग जोन के निकट जंगल में लगी है। जिसको फायर यूनिट द्वारा मो0फा0 इं0 से पम्पिंग कर 01 हौज व होज रील फैलाकर आग को कडी महनत के बाद पूर्ण रूप से बुझा दिया गया। उक्त आग में किसी भी प्रकार की कोई जन हानि नही हुई है। | M7: 50,000/- | N7: 9,50,000/- | O7: - | P7: - | Q7: - | R7: - | S7: - | T7: -
B8: 2316 | C8: 39 | D8: उत्तरकाशी | E8: नौगांव (बडकोट) | F8: 45444 | G8: 0.72986111 | H8: एम.डी.टी. के माध्यम से डंडाल गॉव के निकट जंगल में आग लगने की सूचना प्राप्त हुई जो बडी तेजी से आवासीय बस्ती की और बढ रही है। उक्त सूचना पर त्वरित कार्यवाही करते हुयें फायर यूनिट बडकोट घटना स्थल हेतु रवना हुई तथा घटना स्थल पर पहुॅच कर मो0फ0ई0 से हौज रील फैलाकर आग को बुझाना आरम्भ किया गया एवं आग को आवासीय बस्ती की और आने से रोका गया तथा कडी महनत कर व लगातार पानी का छिडकाव कर आग को पूर्ण रूप से बुझा दिया गया। उक्त आग में स्थानिय लोगो के फल दार वृक्ष जल कर नष्ट हो गये अन्य किसी भी प्रकार की कोई जन हानि नही हुई है। | M8: 50,000/- | N8: 9,50,000/- | O8: - | P8: - | Q8: - | R8: - | S8: - | T8: -
B9: 1006 | C9: 505 | D9: ऊधमसिंहनगर | E9: पन्तनगर | F9: 45444 | G9: 0.34375 | H9: निकट षिवालय हल्दी पन्तनगर यूनिवर्सिटी के निकट घर में लगी आग | I9: संभवतः शार्ट सर्किट से | J9: शॉर्ट सर्किट | K9: घर में रखे बिस्तर एवं सामान में | M9: 150000 | N9: 50000 | O9: - | P9: - | Q9: - | R9: - | S9: - | T9: -
B10: 1023 | C10: 523 | D10: ऊधमसिंहनगर | E10: रूद्रपुर | F10: 45444 | G10: 0.52361111 | H10: पहाड़गंज रूद्रपुर | I10: सम्भवतः लापरवाही पूर्वक धूम्रपान | J10: धूम्रपान | K10: कूडे के ढेर में | M10: शून्य | N10: शून्य | O10: - | P10: - | Q10: - | R10: - | S10: - | T10: -
B11: 1024 | C11: 524 | D11: ऊधमसिंहनगर | E11: रूद्रपुर | F11: 45444 | G11: 0.86180556 | H11: पहाड़गंज रूद्रपुर | I11: सम्भवतः लापरवाही पूर्वक धूम्रपान | J11: धूम्रपान | K11: कूडे के ढेर में | M11: शून्य | N11: शून्य | O11: - | P11: - | Q11: - | R11: - | S11: - | T11: -
B12: 2339 | C12: Rishikesh-1 | D12: देहरादून | E12: ऋषिकेश | F12: 45444 | I12: सम्भवतः अज्ञात व्यक्ति द्वारा लापरवाही से धूम्रपान फेंकने से | J12: धूम्रपान
B13: 337 | C13: 1 | D13: देहरादून | E13: देहरादून | F13: 45444 | G13: 0.63194444 | H13: ्रेसठ पार्क रोड देहरादून | I13: मध्य मार्ग | J13: आधे रास्ते | K13: घर में | L13: घर | M13: - | N13: - | O13: - | P13: - | Q13: - | R13: - | S13: - | T13: -
B14: 338 | C14: 2 | D14: देहरादून | E14: देहरादून | F14: 45444 | G14: 0.69791667 | H14: बंगाली काठी | I14: अज्ञात | J14: अज्ञात | K14: रेस्टोरेन्ट | M14: 20000 | N14: 980000 | O14: - | P14: - | Q14: - | R14: - | S14: - | T14: -
B15: 339 | C15: 3 | D15: देहरादून | E15: देहरादून | F15: 45444 | G15: 0.70833333 | H15: मसूरी रोड फ्रैंड कैफे | I15: अज्ञात | J15: अज्ञात | K15: रेस्टारेन्ट | M15: 500000 | N15: 10000000 | O15: - | P15: - | Q15: - | R15: - | S15: - | T15: -
B16: 340 | C16: 4 | D16: देहरादून | E16: देहरादून | F16: 45444 | G16: 0.98333333 | H16: वैीभव चौक बसन्त विहार | I16: र्षाअ सर्किट | J16: शॉर्ट सर्किट | K16: दुकान | M16: 100000 | N16: 400000 | O16: - | P16: - | Q16: - | R16: - | S16: - | T16: -
B17: 425 | C17: 1 | D17: देहरादून | E17: देहरादून | F17: 45444 | G17: 0.42708333 | H17: मालदेवता | I17: लापरवाही | J17: लापरवाही | K17: जंगल में | M17: 100000 | N17: 1900000 | O17: - | P17: - | Q17: - | R17: - | S17: - | T17: -
B18: 426 | C18: 2 | D18: देहरादून | E18: देहरादून | F18: 45444 | G18: 0.54097222 | H18: गुच्चुपानी | I18: लापरवाही | J18: लापरवाही | K18: जंगल में | M18: 200000 | N18: 300000 | O18: - | P18: - | Q18: - | R18: - | S18: - | T18: -
B19: 427 | C19: 3 | D19: देहरादून | E19: देहरादून | F19: 45444 | G19: 0.56597222 | H19: मीठीबेरी प्रेमनगर | I19: लापरवाही | J19: लापरवाही | K19: जंगल में | M19: 100000 | N19: 300000 | O19: - | P19: - | Q19: - | R19: - | S19: - | T19: -
B20: 428 | C20: 4 | D20: देहरादून | E20: देहरादून | F20: 45444 | G20: 0.61805556 | H20: मालदेवता | I20: लापरवाही | J20: लापरवाही | K20: जंगल में | M20: 100000 | N20: 900000 | O20: - | P20: - | Q20: - | R20: - | S20: - | T20: -
B21: 429 | C21: 5 | D21: देहरादून | E21: देहरादून | F21: 45444 | G21: 0.64097222 | H21: कैनाल रोड षिप्रा रोड | I21: लापरवाही | J21: लापरवाही | K21: जंगल में | M21: 50000 | N21: 1950000 | O21: - | P21: - | Q21: - | R21: - | S21: - | T21: -
B22: 430 | C22: 6 | D22: देहरादून | E22: देहरादून | F22: 45444 | G22: 0.68819444 | H22: चन्द्ररोटी गाूव के पास | I22: लापरवाही | J22: लापरवाही | K22: जंगल में | M22: 50000 | N22: 150000 | O22: - | P22: - | Q22: - | R22: - | S22: - | T22: -
B23: 431 | C23: 7 | D23: देहरादून | E23: देहरादून | F23: 45444 | G23: 0.74652778 | H23: गुनियाल गॉव | I23: लापरवाही | J23: लापरवाही | K23: जंगल में | M23: 200000 | N23: 100000 | O23: - | P23: - | Q23: - | R23: - | S23: - | T23: -
B24: 2473 | C24: Mse-1 | D24: देहरादून | E24: मसूरी | F24: 45444 | G24: 0.70972222 | I24: किचन में सिलेण्डर में आग लगना
B25: 1949 | C25: 1 | D25: देहरादून | E25: विकासनगर | F25: 45444 | G25: 14ः16 | K25: महोदय आग नागथात चुरानी के जगल में हिमालयन रिसोर्ट के पास लगी थी, जिसे फायर सर्विस यूनिट ने वाहन से पंम्पिग कर आग को पूर्ण रूप से बुझाया गया। आग से कोई जनहानि नही हुई है। (आग जगंल में लगी थी) आग की श्रेणी- ए-क्लास फायर | M25: 10000/- | N25: 4990000/- | O25: × | P25: × | Q25: × | R25: × | S25: × | T25: ×
B26: 2502 | C26: sqi-1 | D26: देहरादून | E26: सेलाकुई | F26: 45444
B27: 2246 | C27: 269 | D27: पौड़ी गढ़वाल | E27: कोटद्वार | F27: 45444 | G27: 15:57 बजे | H27: महोदय, मैसर्स फ्यूचर स्टीक अल्टीमेट एनर्जी प्रा0लि0, सोलर प्लांट सतपुली के पास जंगल में आग लगी थी जो सोलर प्लांट की और बढ़ रही थी जिसे फायर यूनिट ने मिनी वाटर टेण्डर से होजरील निकालकर पम्पिंग कर जंगल में लगी आग पर लगातार पानी डालकर पूर्ण रूप से बुझाया गया। आग से कोई जनहानि नहीं हुई। | M27: 1000 | N27: 499000 | O27: - | P27: - | Q27: - | R27: - | S27: - | T27: -
B28: 2199 | C28: 222 | D28: पौड़ी गढ़वाल | E28: पौड़ी | F28: 45444 | G28: 0.4625 | H28: म्होदय, आग शाल्डा गांव कोट ब्लॉक के पास जंगल में लगी थी जो तेजी से घरो की ओर बढ़ रही थी जिसको फायर सर्विस यूनिट ने मोटर फायर ईंजन से 01 होजरील फैलाकर आग को पूर्णरूप से बुझाया आग से किसी प्रकार की जनहानि नहीं हुई। | M28: 1000 | N28: 499000 | O28: - | P28: - | Q28: - | R28: - | S28: - | T28: -
B29: 2200 | C29: 223 | D29: पौड़ी गढ़वाल | E29: पौड़ी | F29: 45444 | G29: 0.47291667 | H29: आग देवप्रयाग रोड़ होटल मुमुक्षू के पास जंगल में लगी थी जो तेजी से होटल व बस्ती की ओर बढ़ रही थी जिसको फायर सर्विस यूनिट ने बुझाना प्रारम्भ किया आग की अधिकता को देखते हुये श्रीमान अग्निशमन अधिकारी महोदय द्वारा दूसरे वाहन की मांग की गयी दोनो फायर यूनिटो ने मिलकर आग को पूर्णरूप से बुझाया। | M29: 1000 | N29: 4999000 | O29: - | P29: - | Q29: - | R29: - | S29: - | T29: -
B30: 2201 | C30: 224 | D30: पौड़ी गढ़वाल | E30: पौड़ी | F30: 45444 | G30: 0.63888889 | H30: प्रभारी अग्निशमन अधिकारी महोदय ने पूर्व से घटनास्थल होटल मुमुक्षू पर तैनात फायर यूनिट को सूचना दी कि ग्राम भट कोट के पास जंगल में आग लगी है जो तेजी से घरो की ओर बढ़ रही है घटनास्थल पर पहुॅचकर फायर यूनिट द्वारा आग को पूर्णरूप से बुझाया गया। | M30: 1000 | N30: 499000 | O30: - | P30: - | Q30: - | R30: - | S30: - | T30: -
B31: 2202 | C31: 225 | D31: पौड़ी गढ़वाल | E31: पौड़ी | F31: 45444 | G31: 0.68888889 | H31: प्रभारी अग्निशमन अधिकारी महोदय ने पूर्व से घटनास्थल ग्राम भटकोट पर तैनात फायर यूनिट को सूचना दी कि चौड़गांव के पास जंगल में आग लगी है जो तेजी से घरो की ओर बढ़ रही है घटनास्थल पर पहुॅचकर फायर यूनिट द्वारा आग को पूर्णरूप से बुझाया गया। | M31: 1000 | N31: 499000 | O31: - | P31: - | Q31: - | R31: - | S31: - | T31: -
B32: 2203 | C32: 226 | D32: पौड़ी गढ़वाल | E32: पौड़ी | F32: 45444 | G32: 0.82152778 | H32: महोदय, आग ग्राम सकेडा में 01 मकान में लगी थी जो काफी दिनो से बन्द पड़ा हुआ था जिसको फायर यूनिट द्वारा एक्स्टिंग्यूशर की मदद से पूर्णरूप से बुझाया गया। | M32: 1000 | N32: 799000 | O32: - | P32: - | Q32: - | R32: - | S32: - | T32: -
B33: 3628 | C33: bgr-7 | D33: बागेश्वर | E33: बागेश्वर | F33: 45444 | G33: 0.66805556 | H33: द्यांगण बाय-पास नीलेष्वर रोड में आवासीय क्षेत्र की ओर बढ़ती जंगल की आग | M33: - | N33: - | O33: - | P33: - | Q33: - | R33: - | S33: - | T33: -
B34: 1435 | C34: 1 | D34: हरिद्वार | E34: मायापुर | F34: 45444 | G34: 0.14166667 | H34: खन्नानगर, ज्वालापुर, हरिद्वार। | I34: सम्भवतः ज्यादा लोड़ पड़ने से इन्वेटर में आग लगी। | K34: आग घर के एक कमरे रखे इन्वेटर में लगी थी आग ई श्रेणी की थी। | L34: घर | M34: 20,000/- | N34: 49,80,000/- | O34: - | P34: - | Q34: - | R34: - | S34: - | T34: -
B35: 1436 | C35: 2 | D35: हरिद्वार | E35: मायापुर | F35: 45444 | G35: 0.15902778 | H35: बी.एच.ई.एल, से0-04, आवास में, हरिद्वार। | I35: आग कही नही मिल फायर सर्विस टीम घटनास्थल से वापस आयी। | K35: . | L35: घर | M35: - | N35: - | O35: - | P35: - | Q35: - | R35: - | S35: -
B36: 1472 | C36: 38 | D36: हरिद्वार | E36: रूड़की | F36: 45444 | G36: 0.066446759 | H36: सुनहरा रोड़ निकट ईदगाह चौक थाना क्ष्ेात्र गंगनहर रूड़की | I36: विद्युत षार्ट सर्किट | J36: शॉर्ट सर्किट | K36: विद्युत ट्रांन्सफार्मर में। | M36: 1000 | N36: 299000 | O36: Nil | P36: Nil | Q36: Nil | R36: Nil | S36: Nil | T36: Nil
B37: 1473 | C37: 39 | D37: हरिद्वार | E37: रूड़की | F37: 45444 | G37: 0.071840278 | H37: मैसर्स अरोमा क्राफ्ट एण्ड टिषूस ग्राम-नूरपुर बुढ़पुर थाना क्षेत्र झबरेड़ा | I37: जांच प्रचलित है। | K37: - | L37: दुकान | M37: - | N37: - | O37: Nil | P37: Nil | Q37: Nil | R37: Nil | S37: 5 | T37: Nil
B38: 1474 | C38: 40 | D38: हरिद्वार | E38: रूड़की | F38: 45444 | G38: 0.7375 | H38: डंपिंग जोन ग्राम-सालियर थाना क्ष्ेात्र गंगनहर रूड़की | I38: सम्भवतः लापरवाही धूम्रपान | J38: धूम्रपान | K38: छपस | M38: Nil | N38: Nil | O38: Nil | P38: Nil | Q38: Nil | R38: Nil | S38: Nil | T38: Nil
B39: 1496 | C39: 62 | D39: हरिद्वार | E39: लक्सर | F39: 45444 | G39: 0.043055556 | H39: ग्राम रायसी | I39: सम्भवत बीडी सिगरेट पीने के कारण | J39: धूम्रपान | K39: गन्ने की खोई में | M39: 170000/= | N39: 130000/= | O39: NIL | P39: NIL | Q39: NIL | R39: NIL | S39: NIL | T39: NIL
B40: 2304 | C40: 27 | D40: उत्तरकाशी | E40: उत्तरकाशी | F40: 45445 | G40: 0.84027778 | H40: आग की सूचना प्राप्त होते ही फायर यूनिट घटना स्थल को रवाना हुए पहुचकर देखा कि आग मनेरा बाईपास रोड पोखरी गांव के समीप जंगल में लगी थी जिसे फायर यूनिट द्वारा मिनी हायर प्रेशर एवं एम0एफ0ई0 से पम्पिंग कर होज पाईप फेलाकर आग को पूर्णरूप से बुझाया बाद अग्निशमन कार्य के फायर यूनिट वाहन मे पानी भर कर जल संस्थाान से वापास एफएस पर उपस्थित हुए। | M40: 5000 | N40: 1995000 | O40: - | P40: - | Q40: - | R40: - | S40: - | T40: -
B41: 2317 | C41: 40 | D41: उत्तरकाशी | E41: नौगांव (बडकोट) | F41: 45445 | G41: 0.32638889 | H41: थानाध्यक्ष महोदय बडकोट द्वारा स्टेशन प्रभारी के मोबाईल पर रा0महाविघालय टटाऊ के निकट जंगल व झाडियों में आग लगने की सूचना दी सूचना प्रात्प होते ही फायर यूनिट बडकोट घटना स्थल पर पहुॅची तथा देखा की आग जंगल व झाडियो में थी जोकि हवा के तेज बहाव के कारण टटाऊ में चल रही कथा पंडाल के निकट आ रही थी जिसको फायर यूनिट द्वारा मो0फा0 इं0 से पम्पिंग कर 01 हौज फैलाकर आग को कडी महनत के बाद पूर्ण रूप से बुझा दिया गया। उक्त आग में किसी भी प्रकार की कोई जन हानि नही हुई है। | M41: 1,00,000/- | N41: 49,00,000/- | O41: - | P41: - | Q41: - | R41: - | S41: - | T41: -
...

Sheet Sheet2
C2: फायर कॉल -2024
C4: क्र0सं0 | D4: जनपद | E4: फायर स्टेशन | F4: जनवरी | H4: फरवरी | J4: मार्च | L4: अप्रैल | N4: मई | P4: जून | R4: जुलाई | T4: अगस्त | V4: सितम्बर | X4: अक्टूबर | Z4: नवम्बर | AB4: दिसम्बर | AD4: योग
C5: 1 | D5: Dehradun | E5: देहरादून | F5: =COUNTIFS(Table1[(जिस फायर स्टेशन क्षेत्रार्न्तागत अग्निकाण्ड हुआ हो)],Sheet2!E5,Table1[अग्निकाण्ड का दिनांक],">="&DATE(2024,1,1), Table1[अग्निकाण्ड का दिनांक],"<="&EOMONTH(DATE(2024,1,1),0)) -> 0 | G5: 36 | H5: =COUNTIFS(Table1[(जिस फायर स्टेशन क्षेत्रार्न्तागत अग्निकाण्ड हुआ हो)],Sheet2!E5,Table1[अग्निकाण्ड का दिनांक],">="&DATE(2024,2,1), Table1[अग्निकाण्ड का दिनांक],"<="&EOMONTH(DATE(2024,2,1),0)) -> 0 | I5: 24 | J5: =COUNTIFS(Table1[(जिस फायर स्टेशन क्षेत्रार्न्तागत अग्निकाण्ड हुआ हो)],Sheet2!E5,Table1[अग्निकाण्ड का दिनांक],">="&DATE(2024,3,1), Table1[अग्निकाण्ड का दिनांक],"<="&EOMONTH(DATE(2024,3,1),0)) -> 0 | K5: 34 | L5: =COUNTIFS(Table1[(जिस फायर स्टेशन क्षेत्रार्न्तागत अग्निकाण्ड हुआ हो)],Sheet2!E5,Table1[अग्निकाण्ड का दिनांक],">="&DATE(2024,4,1), Table1[अग्निकाण्ड का दिनांक],"<="&EOMONTH(DATE(2024,4,1),0)) -> 0 | M5: 116 | N5: =COUNTIFS(Table1[(जिस फायर स्टेशन क्षेत्रार्न्तागत अग्निकाण्ड हुआ हो)],Sheet2!E5,Table1[अग्निकाण्ड का दिनांक],">="&DATE(2024,5,1), Table1[अग्निकाण्ड का दिनांक],"<="&EOMONTH(DATE(2024,5,1),0)) -> 0 | O5: 133 | P5: =COUNTIFS(Table1[(जिस फायर स्टेशन क्षेत्रार्न्तागत अग्निकाण्ड हुआ हो)],Sheet2!E5,Table1[अग्निकाण्ड का दिनांक],">="&DATE(2024,6,1), Table1[अग्निकाण्ड का दिनांक],"<="&EOMONTH(DATE(2024,6,1),0)) -> 119 | Q5: 119 | R5: =COUNTIFS(Table1[(जिस फायर स्टेशन क्षेत्रार्न्तागत अग्निकाण्ड हुआ हो)],Sheet2!E5,Table1[अग्निकाण्ड का दिनांक],">="&DATE(2024,7,1), Table1[अग्निकाण्ड का दिनांक],"<="&EOMONTH(DATE(2024,7,1),0)) -> 0 | S5: 17 | T5: =COUNTIFS(Table1[(जिस फायर स्टेशन क्षेत्रार्न्तागत अग्निकाण्ड हुआ हो)],Sheet2!E5,Table1[अग्निकाण्ड का दिनांक],">="&DATE(2024,8,1), Table1[अग्निकाण्ड का दिनांक],"<="&EOMONTH(DATE(2024,8,1),0)) -> 0 | U5: 11 | V5: =COUNTIFS(Table1[(जिस फायर स्टेशन क्षेत्रार्न्तागत अग्निकाण्ड हुआ हो)],Sheet2!E5,Table1[अग्निकाण्ड का दिनांक],">="&DATE(2024,9,1), Table1[अग्निकाण्ड का दिनांक],"<="&EOMONTH(DATE(2024,9,1),0)) -> 0 | W5: 15 | X5: =COUNTIFS(Table1[(जिस फायर स्टेशन क्षेत्रार्न्तागत अग्निकाण्ड हुआ हो)],Sheet2!E5,Table1[अग्निकाण्ड का दिनांक],">="&DATE(2024,10,1), Table1[अग्निकाण्ड का दिनांक],"<="&EOMONTH(DATE(2024,10,1),0)) -> 0 | Y5: 31 | Z5: =COUNTIFS(Table1[(जिस फायर स्टेशन क्षेत्रार्न्तागत अग्निकाण्ड हुआ हो)],Sheet2!E5,Table1[अग्निकाण्ड का दिनांक],">="&DATE(2024,11,1), Table1[अग्निकाण्ड का दिनांक],"<="&EOMONTH(DATE(2024,11,1),0)) -> 0 | AA5: 33 | AB5: =COUNTIFS(Table1[(जिस फायर स्टेशन क्षेत्रार्न्तागत अग्निकाण्ड हुआ हो)],Sheet2!E5,Table1[अग्निकाण्ड का दिनांक],">="&DATE(2024,12,1), Table1[अग्निकाण्ड का दिनांक],"<="&EOMONTH(DATE(2024,12,1),0)) -> 0 | AC5: 30 | AD5: =F5+H5+J5+L5+N5+P5+R5+T5+V5+X5+Z5+AB5 -> 119 | AE5: =G5+I5+K5+M5+O5+Q5+S5+U5+W5+Y5+AA5+AC5 -> 599
C6: 2 | E6: ऋषिकेश | F6: =COUNTIFS(Table1[(जिस फायर स्टेशन क्षेत्रार्न्तागत अग्निकाण्ड हुआ हो)],Sheet2!E6,Table1[अग्निकाण्ड का दिनांक],">="&DATE(2024,1,1), Table1[अग्निकाण्ड का दिनांक],"<="&EOMONTH(DATE(2024,1,1),0)) -> 0 | G6: 6 | H6: =COUNTIFS(Table1[(जिस फायर स्टेशन क्षेत्रार्न्तागत अग्निकाण्ड हुआ हो)],Sheet2!E6,Table1[अग्निकाण्ड का दिनांक],">="&DATE(2024,2,1), Table1[अग्निकाण्ड का दिनांक],"<="&EOMONTH(DATE(2024,2,1),0)) -> 0 | I6: 5 | J6: =COUNTIFS(Table1[(जिस फायर स्टेशन क्षेत्रार्न्तागत अग्निकाण्ड हुआ हो)],Sheet2!E6,Table1[अग्निकाण्ड का दिनांक],">="&DATE(2024,3,1), Table1[अग्निकाण्ड का दिनांक],"<="&EOMONTH(DATE(2024,3,1),0)) -> 0 | K6: 7 | L6: =COUNTIFS(Table1[(जिस फायर स्टेशन क्षेत्रार्न्तागत अग्निकाण्ड हुआ हो)],Sheet2!E6,Table1[अग्निकाण्ड का दिनांक],">="&DATE(2024,4,1), Table1[अग्निकाण्ड का दिनांक],"<="&EOMONTH(DATE(2024,4,1),0)) -> 0 | M6: 21 | N6: =COUNTIFS(Table1[(जिस फायर स्टेशन क्षेत्रार्न्तागत अग्निकाण्ड हुआ हो)],Sheet2!E6,Table1[अग्निकाण्ड का दिनांक],">="&DATE(2024,5,1), Table1[अग्निकाण्ड का दिनांक],"<="&EOMONTH(DATE(2024,5,1),0)) -> 0 | O6: 30 | P6: =COUNTIFS(Table1[(जिस फायर स्टेशन क्षेत्रार्न्तागत अग्निकाण्ड हुआ हो)],Sheet2!E6,Table1[अग्निकाण्ड का दिनांक],">="&DATE(2024,6,1), Table1[अग्निकाण्ड का दिनांक],"<="&EOMONTH(DATE(2024,6,1),0)) -> 26 | Q6: 26 | R6: =COUNTIFS(Table1[(जिस फायर स्टेशन क्षेत्रार्न्तागत अग्निकाण्ड हुआ हो)],Sheet2!E6,Table1[अग्निकाण्ड का दिनांक],">="&DATE(2024,7,1), Table1[अग्निकाण्ड का दिनांक],"<="&EOMONTH(DATE(2024,7,1),0)) -> 0 | S6: 7 | T6: =COUNTIFS(Table1[(जिस फायर स्टेशन क्षेत्रार्न्तागत अग्निकाण्ड हुआ हो)],Sheet2!E6,Table1[अग्निकाण्ड का दिनांक],">="&DATE(2024,8,1), Table1[अग्निकाण्ड का दिनांक],"<="&EOMONTH(DATE(2024,8,1),0)) -> 0 | U6: 3 | V6: =COUNTIFS(Table1[(जिस फायर स्टेशन क्षेत्रार्न्तागत अग्निकाण्ड हुआ हो)],Sheet2!E6,Table1[अग्निकाण्ड का दिनांक],">="&DATE(2024,9,1), Table1[अग्निकाण्ड का दिनांक],"<="&EOMONTH(DATE(2024,9,1),0)) -> 0 | W6: 2 | X6: =COUNTIFS(Table1[(जिस फायर स्टेशन क्षेत्रार्न्तागत अग्निकाण्ड हुआ हो)],Sheet2!E6,Table1[अग्निकाण्ड का दिनांक],">="&DATE(2024,10,1), Table1[अग्निकाण्ड का दिनांक],"<="&EOMONTH(DATE(2024,10,1),0)) -> 0 | Y6: 11 | Z6: =COUNTIFS(Table1[(जिस फायर स्टेशन क्षेत्रार्न्तागत अग्निकाण्ड हुआ हो)],Sheet2!E6,Table1[अग्निकाण्ड का दिनांक],">="&DATE(2024,11,1), Table1[अग्निकाण्ड का दिनांक],"<="&EOMONTH(DATE(2024,11,1),0)) -> 0 | AA6: 7 | AB6: =COUNTIFS(Table1[(जिस फायर स्टेशन क्षेत्रार्न्तागत अग्निकाण्ड हुआ हो)],Sheet2!E6,Table1[अग्निकाण्ड का दिनांक],">="&DATE(2024,12,1), Table1[अग्निकाण्ड का दिनांक],"<="&EOMONTH(DATE(2024,12,1),0)) -> 0 | AC6: 9 | AD6: =F6+H6+J6+L6+N6+P6+R6+T6+V6+X6+Z6+AB6 -> 26 | AE6: =G6+I6+K6+M6+O6+Q6+S6+U6+W6+Y6+AA6+AC6 -> 134
C7: 3 | E7: मसूरी | F7: =COUNTIFS(Table1[(जिस फायर स्टेशन क्षेत्रार्न्तागत अग्निकाण्ड हुआ हो)],Sheet2!E7,Table1[अग्निकाण्ड का दिनांक],">="&DATE(2024,1,1), Table1[अग्निकाण्ड का दिनांक],"<="&EOMONTH(DATE(2024,1,1),0)) -> 0 | G7: 5 | H7: =COUNTIFS(Table1[(जिस फायर स्टेशन क्षेत्रार्न्तागत अग्निकाण्ड हुआ हो)],Sheet2!E7,Table1[अग्निकाण्ड का दिनांक],">="&DATE(2024,2,1), Table1[अग्निकाण्ड का दिनांक],"<="&EOMONTH(DATE(2024,2,1),0)) -> 0 | I7: 0 | J7: =COUNTIFS(Table1[(जिस फायर स्टेशन क्षेत्रार्न्तागत अग्निकाण्ड हुआ हो)],Sheet2!E7,Table1[अग्निकाण्ड का दिनांक],">="&DATE(2024,3,1), Table1[अग्निकाण्ड का दिनांक],"<="&EOMONTH(DATE(2024,3,1),0)) -> 0 | K7: 0 | L7: =COUNTIFS(Table1[(जिस फायर स्टेशन क्षेत्रार्न्तागत अग्निकाण्ड हुआ हो)],Sheet2!E7,Table1[अग्निकाण्ड का दिनांक],">="&DATE(2024,4,1), Table1[अग्निकाण्ड का दिनांक],"<="&EOMONTH(DATE(2024,4,1),0)) -> 0 | M7: 5 | N7: =COUNTIFS(Table1[(जिस फायर स्टेशन क्षेत्रार्न्तागत अग्निकाण्ड हुआ हो)],Sheet2!E7,Table1[अग्निकाण्ड का दिनांक],">="&DATE(2024,5,1), Table1[अग्निकाण्ड का दिनांक],"<="&EOMONTH(DATE(2024,5,1),0)) -> 0 | O7: 9 | P7: =COUNTIFS(Table1[(जिस फायर स्टेशन क्षेत्रार्न्तागत अग्निकाण्ड हुआ हो)],Sheet2!E7,Table1[अग्निकाण्ड का दिनांक],">="&DATE(2024,6,1), Table1[अग्निकाण्ड का दिनांक],"<="&EOMONTH(DATE(2024,6,1),0)) -> 6 | Q7: 6 | R7: =COUNTIFS(Table1[(जिस फायर स्टेशन क्षेत्रार्न्तागत अग्निकाण्ड हुआ हो)],Sheet2!E7,Table1[अग्निकाण्ड का दिनांक],">="&DATE(2024,7,1), Table1[अग्निकाण्ड का दिनांक],"<="&EOMONTH(DATE(2024,7,1),0)) -> 0 | S7: 0 | T7: =COUNTIFS(Table1[(जिस फायर स्टेशन क्षेत्रार्न्तागत अग्निकाण्ड हुआ हो)],Sheet2!E7,Table1[अग्निकाण्ड का दिनांक],">="&DATE(2024,8,1), Table1[अग्निकाण्ड का दिनांक],"<="&EOMONTH(DATE(2024,8,1),0)) -> 0 | U7: 0 | V7: =COUNTIFS(Table1[(जिस फायर स्टेशन क्षेत्रार्न्तागत अग्निकाण्ड हुआ हो)],Sheet2!E7,Table1[अग्निकाण्ड का दिनांक],">="&DATE(2024,9,1), Table1[अग्निकाण्ड का दिनांक],"<="&EOMONTH(DATE(2024,9,1),0)) -> 0 | W7: 0 | X7: =COUNTIFS(Table1[(जिस फायर स्टेशन क्षेत्रार्न्तागत अग्निकाण्ड हुआ हो)],Sheet2!E7,Table1[अग्निकाण्ड का दिनांक],">="&DATE(2024,10,1), Table1[अग्निकाण्ड का दिनांक],"<="&EOMONTH(DATE(2024,10,1),0)) -> 0 | Y7: 0 | Z7: =COUNTIFS(Table1[(जिस फायर स्टेशन क्षेत्रार्न्तागत अग्निकाण्ड हुआ हो)],Sheet2!E7,Table1[अग्निकाण्ड का दिनांक],">="&DATE(2024,11,1), Table1[अग्निकाण्ड का दिनांक],"<="&EOMONTH(DATE(2024,11,1),0)) -> 0 | AA7: 1 | AB7: =COUNTIFS(Table1[(जिस फायर स्टेशन क्षेत्रार्न्तागत अग्निकाण्ड हुआ हो)],Sheet2!E7,Table1[अग्निकाण्ड का दिनांक],">="&DATE(2024,12,1), Table1[अग्निकाण्ड का दिनांक],"<="&EOMONTH(DATE(2024,12,1),0)) -> 0 | AC7: 3 | AD7: =F7+H7+J7+L7+N7+P7+R7+T7+V7+X7+Z7+AB7 -> 6 | AE7: =G7+I7+K7+M7+O7+Q7+S7+U7+W7+Y7+AA7+AC7 -> 29
C8: 4 | E8: विकासनगर | F8: =COUNTIFS(Table1[(जिस फायर स्टेशन क्षेत्रार्न्तागत अग्निकाण्ड हुआ हो)],Sheet2!E8,Table1[अग्निकाण्ड का दिनांक],">="&DATE(2024,1,1), Table1[अग्निकाण्ड का दिनांक],"<="&EOMONTH(DATE(2024,1,1),0)) -> 0 | G8: 2 | H8: =COUNTIFS(Table1[(जिस फायर स्टेशन क्षेत्रार्न्तागत अग्निकाण्ड हुआ हो)],Sheet2!E8,Table1[अग्निकाण्ड का दिनांक],">="&DATE(2024,2,1), Table1[अग्निकाण्ड का दिनांक],"<="&EOMONTH(DATE(2024,2,1),0)) -> 0 | I8: 1 | J8: =COUNTIFS(Table1[(जिस फायर स्टेशन क्षेत्रार्न्तागत अग्निकाण्ड हुआ हो)],Sheet2!E8,Table1[अग्निकाण्ड का दिनांक],">="&DATE(2024,3,1), Table1[अग्निकाण्ड का दिनांक],"<="&EOMONTH(DATE(2024,3,1),0)) -> 0 | K8: 4 | L8: =COUNTIFS(Table1[(जिस फायर स्टेशन क्षेत्रार्न्तागत अग्निकाण्ड हुआ हो)],Sheet2!E8,Table1[अग्निकाण्ड का दिनांक],">="&DATE(2024,4,1), Table1[अग्निकाण्ड का दिनांक],"<="&EOMONTH(DATE(2024,4,1),0)) -> 0 | M8: 10 | N8: =COUNTIFS(Table1[(जिस फायर स्टेशन क्षेत्रार्न्तागत अग्निकाण्ड हुआ हो)],Sheet2!E8,Table1[अग्निकाण्ड का दिनांक],">="&DATE(2024,5,1), Table1[अग्निकाण्ड का दिनांक],"<="&EOMONTH(DATE(2024,5,1),0)) -> 0 | O8: 26 | P8: =COUNTIFS(Table1[(जिस फायर स्टेशन क्षेत्रार्न्तागत अग्निकाण्ड हुआ हो)],Sheet2!E8,Table1[अग्निकाण्ड का दिनांक],">="&DATE(2024,6,1), Table1[अग्निकाण्ड का दिनांक],"<="&EOMONTH(DATE(2024,6,1),0)) -> 11 | Q8: 11 | R8: =COUNTIFS(Table1[(जिस फायर स्टेशन क्षेत्रार्न्तागत अग्निकाण्ड हुआ हो)],Sheet2!E8,Table1[अग्निकाण्ड का दिनांक],">="&DATE(2024,7,1), Table1[अग्निकाण्ड का दिनांक],"<="&EOMONTH(DATE(2024,7,1),0)) -> 0 | S8: 0 | T8: =COUNTIFS(Table1[(जिस फायर स्टेशन क्षेत्रार्न्तागत अग्निकाण्ड हुआ हो)],Sheet2!E8,Table1[अग्निकाण्ड का दिनांक],">="&DATE(2024,8,1), Table1[अग्निकाण्ड का दिनांक],"<="&EOMONTH(DATE(2024,8,1),0)) -> 0 | U8: 1 | V8: =COUNTIFS(Table1[(जिस फायर स्टेशन क्षेत्रार्न्तागत अग्निकाण्ड हुआ हो)],Sheet2!E8,Table1[अग्निकाण्ड का दिनांक],">="&DATE(2024,9,1), Table1[अग्निकाण्ड का दिनांक],"<="&EOMONTH(DATE(2024,9,1),0)) -> 0 | W8: 2 | X8: =COUNTIFS(Table1[(जिस फायर स्टेशन क्षेत्रार्न्तागत अग्निकाण्ड हुआ हो)],Sheet2!E8,Table1[अग्निकाण्ड का दिनांक],">="&DATE(2024,10,1), Table1[अग्निकाण्ड का दिनांक],"<="&EOMONTH(DATE(2024,10,1),0)) -> 0 | Y8: 1 | Z8: =COUNTIFS(Table1[(जिस फायर स्टेशन क्षेत्रार्न्तागत अग्निकाण्ड हुआ हो)],Sheet2!E8,Table1[अग्निकाण्ड का दिनांक],">="&DATE(2024,11,1), Table1[अग्निकाण्ड का दिनांक],"<="&EOMONTH(DATE(2024,11,1),0)) -> 0 | AA8: 7 | AB8: =COUNTIFS(Table1[(जिस फायर स्टेशन क्षेत्रार्न्तागत अग्निकाण्ड हुआ हो)],Sheet2!E8,Table1[अग्निकाण्ड का दिनांक],">="&DATE(2024,12,1), Table1[अग्निकाण्ड का दिनांक],"<="&EOMONTH(DATE(2024,12,1),0)) -> 0 | AC8: 6 | AD8: =F8+H8+J8+L8+N8+P8+R8+T8+V8+X8+Z8+AB8 -> 11 | AE8: =G8+I8+K8+M8+O8+Q8+S8+U8+W8+Y8+AA8+AC8 -> 71
C9: 5 | E9: सेलाकुई | F9: =COUNTIFS(Table1[(जिस फायर स्टेशन क्षेत्रार्न्तागत अग्निकाण्ड हुआ हो)],Sheet2!E9,Table1[अग्निकाण्ड का दिनांक],">="&DATE(2024,1,1), Table1[अग्निकाण्ड का दिनांक],"<="&EOMONTH(DATE(2024,1,1),0)) -> 0 | G9: 5 | H9: =COUNTIFS(Table1[(जिस फायर स्टेशन क्षेत्रार्न्तागत अग्निकाण्ड हुआ हो)],Sheet2!E9,Table1[अग्निकाण्ड का दिनांक],">="&DATE(2024,2,1), Table1[अग्निकाण्ड का दिनांक],"<="&EOMONTH(DATE(2024,2,1),0)) -> 0 | I9: 4 | J9: =COUNTIFS(Table1[(जिस फायर स्टेशन क्षेत्रार्न्तागत अग्निकाण्ड हुआ हो)],Sheet2!E9,Table1[अग्निकाण्ड का दिनांक],">="&DATE(2024,3,1), Table1[अग्निकाण्ड का दिनांक],"<="&EOMONTH(DATE(2024,3,1),0)) -> 0 | K9: 7 | L9: =COUNTIFS(Table1[(जिस फायर स्टेशन क्षेत्रार्न्तागत अग्निकाण्ड हुआ हो)],Sheet2!E9,Table1[अग्निकाण्ड का दिनांक],">="&DATE(2024,4,1), Table1[अग्निकाण्ड का दिनांक],"<="&EOMONTH(DATE(2024,4,1),0)) -> 0 | M9: 22 | N9: =COUNTIFS(Table1[(जिस फायर स्टेशन क्षेत्रार्न्तागत अग्निकाण्ड हुआ हो)],Sheet2!E9,Table1[अग्निकाण्ड का दिनांक],">="&DATE(2024,5,1), Table1[अग्निकाण्ड का दिनांक],"<="&EOMONTH(DATE(2024,5,1),0)) -> 0 | O9: 34 | P9: =COUNTIFS(Table1[(जिस फायर स्टेशन क्षेत्रार्न्तागत अग्निकाण्ड हुआ हो)],Sheet2!E9,Table1[अग्निकाण्ड का दिनांक],">="&DATE(2024,6,1), Table1[अग्निकाण्ड का दिनांक],"<="&EOMONTH(DATE(2024,6,1),0)) -> 1 | Q9: 30 | R9: =COUNTIFS(Table1[(जिस फायर स्टेशन क्षेत्रार्न्तागत अग्निकाण्ड हुआ हो)],Sheet2!E9,Table1[अग्निकाण्ड का दिनांक],">="&DATE(2024,7,1), Table1[अग्निकाण्ड का दिनांक],"<="&EOMONTH(DATE(2024,7,1),0)) -> 0 | S9: 1 | T9: =COUNTIFS(Table1[(जिस फायर स्टेशन क्षेत्रार्न्तागत अग्निकाण्ड हुआ हो)],Sheet2!E9,Table1[अग्निकाण्ड का दिनांक],">="&DATE(2024,8,1), Table1[अग्निकाण्ड का दिनांक],"<="&EOMONTH(DATE(2024,8,1),0)) -> 0 | U9: 2 | V9: =COUNTIFS(Table1[(जिस फायर स्टेशन क्षेत्रार्न्तागत अग्निकाण्ड हुआ हो)],Sheet2!E9,Table1[अग्निकाण्ड का दिनांक],">="&DATE(2024,9,1), Table1[अग्निकाण्ड का दिनांक],"<="&EOMONTH(DATE(2024,9,1),0)) -> 0 | W9: 2 | X9: =COUNTIFS(Table1[(जिस फायर स्टेशन क्षेत्रार्न्तागत अग्निकाण्ड हुआ हो)],Sheet2!E9,Table1[अग्निकाण्ड का दिनांक],">="&DATE(2024,10,1), Table1[अग्निकाण्ड का दिनांक],"<="&EOMONTH(DATE(2024,10,1),0)) -> 0 | Y9: 1 | Z9: =COUNTIFS(Table1[(जिस फायर स्टेशन क्षेत्रार्न्तागत अग्निकाण्ड हुआ हो)],Sheet2!E9,Table1[अग्निकाण्ड का दिनांक],">="&DATE(2024,11,1), Table1[अग्निकाण्ड का दिनांक],"<="&EOMONTH(DATE(2024,11,1),0)) -> 0 | AA9: 1 | AB9: =COUNTIFS(Table1[(जिस फायर स्टेशन क्षेत्रार्न्तागत अग्निकाण्ड हुआ हो)],Sheet2!E9,Table1[अग्निकाण्ड का दिनांक],">="&DATE(2024,12,1), Table1[अग्निकाण्ड का दिनांक],"<="&EOMONTH(DATE(2024,12,1),0)) -> 0 | AC9: 4 | AD9: =F9+H9+J9+L9+N9+P9+R9+T9+V9+X9+Z9+AB9 -> 1 | AE9: =G9+I9+K9+M9+O9+Q9+S9+U9+W9+Y9+AA9+AC9 -> 113
C10: 6 | E10: डोईवाला | F10: =COUNTIFS(Table1[(जिस फायर स्टेशन क्षेत्रार्न्तागत अग्निकाण्ड हुआ हो)],Sheet2!E10,Table1[अग्निकाण्ड का दिनांक],">="&DATE(2024,1,1), Table1[अग्निकाण्ड का दिनांक],"<="&EOMONTH(DATE(2024,1,1),0)) -> 0 | G10: 1 | H10: =COUNTIFS(Table1[(जिस फायर स्टेशन क्षेत्रार्न्तागत अग्निकाण्ड हुआ हो)],Sheet2!E10,Table1[अग्निकाण्ड का दिनांक],">="&DATE(2024,2,1), Table1[अग्निकाण्ड का दिनांक],"<="&EOMONTH(DATE(2024,2,1),0)) -> 0 | I10: 1 | J10: =COUNTIFS(Table1[(जिस फायर स्टेशन क्षेत्रार्न्तागत अग्निकाण्ड हुआ हो)],Sheet2!E10,Table1[अग्निकाण्ड का दिनांक],">="&DATE(2024,3,1), Table1[अग्निकाण्ड का दिनांक],"<="&EOMONTH(DATE(2024,3,1),0)) -> 0 | K10: 3 | L10: =COUNTIFS(Table1[(जिस फायर स्टेशन क्षेत्रार्न्तागत अग्निकाण्ड हुआ हो)],Sheet2!E10,Table1[अग्निकाण्ड का दिनांक],">="&DATE(2024,4,1), Table1[अग्निकाण्ड का दिनांक],"<="&EOMONTH(DATE(2024,4,1),0)) -> 0 | M10: 3 | N10: =COUNTIFS(Table1[(जिस फायर स्टेशन क्षेत्रार्न्तागत अग्निकाण्ड हुआ हो)],Sheet2!E10,Table1[अग्निकाण्ड का दिनांक],">="&DATE(2024,5,1), Table1[अग्निकाण्ड का दिनांक],"<="&EOMONTH(DATE(2024,5,1),0)) -> 0 | O10: 7 | P10: =COUNTIFS(Table1[(जिस फायर स्टेशन क्षेत्रार्न्तागत अग्निकाण्ड हुआ हो)],Sheet2!E10,Table1[अग्निकाण्ड का दिनांक],">="&DATE(2024,6,1), Table1[अग्निकाण्ड का दिनांक],"<="&EOMONTH(DATE(2024,6,1),0)) -> 0 | Q10: 3 | R10: =COUNTIFS(Table1[(जिस फायर स्टेशन क्षेत्रार्न्तागत अग्निकाण्ड हुआ हो)],Sheet2!E10,Table1[अग्निकाण्ड का दिनांक],">="&DATE(2024,7,1), Table1[अग्निकाण्ड का दिनांक],"<="&EOMONTH(DATE(2024,7,1),0)) -> 0 | S10: 2 | T10: =COUNTIFS(Table1[(जिस फायर स्टेशन क्षेत्रार्न्तागत अग्निकाण्ड हुआ हो)],Sheet2!E10,Table1[अग्निकाण्ड का दिनांक],">="&DATE(2024,8,1), Table1[अग्निकाण्ड का दिनांक],"<="&EOMONTH(DATE(2024,8,1),0)) -> 0 | U10: 0 | V10: =COUNTIFS(Table1[(जिस फायर स्टेशन क्षेत्रार्न्तागत अग्निकाण्ड हुआ हो)],Sheet2!E10,Table1[अग्निकाण्ड का दिनांक],">="&DATE(2024,9,1), Table1[अग्निकाण्ड का दिनांक],"<="&EOMONTH(DATE(2024,9,1),0)) -> 0 | W10: 2 | X10: =COUNTIFS(Table1[(जिस फायर स्टेशन क्षेत्रार्न्तागत अग्निकाण्ड हुआ हो)],Sheet2!E10,Table1[अग्निकाण्ड का दिनांक],">="&DATE(2024,10,1), Table1[अग्निकाण्ड का दिनांक],"<="&EOMONTH(DATE(2024,10,1),0)) -> 0 | Y10: 4 | Z10: =COUNTIFS(Table1[(जिस फायर स्टेशन क्षेत्रार्न्तागत अग्निकाण्ड हुआ हो)],Sheet2!E10,Table1[अग्निकाण्ड का दिनांक],">="&DATE(2024,11,1), Table1[अग्निकाण्ड का दिनांक],"<="&EOMONTH(DATE(2024,11,1),0)) -> 0 | AA10: 5 | AB10: =COUNTIFS(Table1[(जिस फायर स्टेशन क्षेत्रार्न्तागत अग्निकाण्ड हुआ हो)],Sheet2!E10,Table1[अग्निकाण्ड का दिनांक],">="&DATE(2024,12,1), Table1[अग्निकाण्ड का दिनांक],"<="&EOMONTH(DATE(2024,12,1),0)) -> 0 | AC10: 1 | AD10: =F10+H10+J10+L10+N10+P10+R10+T10+V10+X10+Z10+AB10 -> 0 | AE10: =G10+I10+K10+M10+O10+Q10+S10+U10+W10+Y10+AA10+AC10 -> 32
C11: 7 | E11: त्यूनी | F11: =COUNTIFS(Table1[(जिस फायर स्टेशन क्षेत्रार्न्तागत अग्निकाण्ड हुआ हो)],Sheet2!E11,Table1[अग्निकाण्ड का दिनांक],">="&DATE(2024,1,1), Table1[अग्निकाण्ड का दिनांक],"<="&EOMONTH(DATE(2024,1,1),0)) -> 0 | G11: 1 | H11: =COUNTIFS(Table1[(जिस फायर स्टेशन क्षेत्रार्न्तागत अग्निकाण्ड हुआ हो)],Sheet2!E11,Table1[अग्निकाण्ड का दिनांक],">="&DATE(2024,2,1), Table1[अग्निकाण्ड का दिनांक],"<="&EOMONTH(DATE(2024,2,1),0)) -> 0 | I11: 0 | J11: =COUNTIFS(Table1[(जिस फायर स्टेशन क्षेत्रार्न्तागत अग्निकाण्ड हुआ हो)],Sheet2!E11,Table1[अग्निकाण्ड का दिनांक],">="&DATE(2024,3,1), Table1[अग्निकाण्ड का दिनांक],"<="&EOMONTH(DATE(2024,3,1),0)) -> 0 | K11: 0 | L11: =COUNTIFS(Table1[(जिस फायर स्टेशन क्षेत्रार्न्तागत अग्निकाण्ड हुआ हो)],Sheet2!E11,Table1[अग्निकाण्ड का दिनांक],">="&DATE(2024,4,1), Table1[अग्निकाण्ड का दिनांक],"<="&EOMONTH(DATE(2024,4,1),0)) -> 0 | M11: 1 | N11: =COUNTIFS(Table1[(जिस फायर स्टेशन क्षेत्रार्न्तागत अग्निकाण्ड हुआ हो)],Sheet2!E11,Table1[अग्निकाण्ड का दिनांक],">="&DATE(2024,5,1), Table1[अग्निकाण्ड का दिनांक],"<="&EOMONTH(DATE(2024,5,1),0)) -> 0 | O11: 4 | P11: =COUNTIFS(Table1[(जिस फायर स्टेशन क्षेत्रार्न्तागत अग्निकाण्ड हुआ हो)],Sheet2!E11,Table1[अग्निकाण्ड का दिनांक],">="&DATE(2024,6,1), Table1[अग्निकाण्ड का दिनांक],"<="&EOMONTH(DATE(2024,6,1),0)) -> 3 | Q11: 3 | R11: =COUNTIFS(Table1[(जिस फायर स्टेशन क्षेत्रार्न्तागत अग्निकाण्ड हुआ हो)],Sheet2!E11,Table1[अग्निकाण्ड का दिनांक],">="&DATE(2024,7,1), Table1[अग्निकाण्ड का दिनांक],"<="&EOMONTH(DATE(2024,7,1),0)) -> 0 | S11: 0 | T11: =COUNTIFS(Table1[(जिस फायर स्टेशन क्षेत्रार्न्तागत अग्निकाण्ड हुआ हो)],Sheet2!E11,Table1[अग्निकाण्ड का दिनांक],">="&DATE(2024,8,1), Table1[अग्निकाण्ड का दिनांक],"<="&EOMONTH(DATE(2024,8,1),0)) -> 0 | U11: 0 | V11: =COUNTIFS(Table1[(जिस फायर स्टेशन क्षेत्रार्न्तागत अग्निकाण्ड हुआ हो)],Sheet2!E11,Table1[अग्निकाण्ड का दिनांक],">="&DATE(2024,9,1), Table1[अग्निकाण्ड का दिनांक],"<="&EOMONTH(DATE(2024,9,1),0)) -> 0 | W11: 0 | X11: =COUNTIFS(Table1[(जिस फायर स्टेशन क्षेत्रार्न्तागत अग्निकाण्ड हुआ हो)],Sheet2!E11,Table1[अग्निकाण्ड का दिनांक],">="&DATE(2024,10,1), Table1[अग्निकाण्ड का दिनांक],"<="&EOMONTH(DATE(2024,10,1),0)) -> 0 | Y11: 0 | Z11: =COUNTIFS(Table1[(जिस फायर स्टेशन क्षेत्रार्न्तागत अग्निकाण्ड हुआ हो)],Sheet2!E11,Table1[अग्निकाण्ड का दिनांक],">="&DATE(2024,11,1), Table1[अग्निकाण्ड का दिनांक],"<="&EOMONTH(DATE(2024,11,1),0)) -> 0 | AA11: 0 | AB11: =COUNTIFS(Table1[(जिस फायर स्टेशन क्षेत्रार्न्तागत अग्निकाण्ड हुआ हो)],Sheet2!E11,Table1[अग्निकाण्ड का दिनांक],">="&DATE(2024,12,1), Table1[अग्निकाण्ड का दिनांक],"<="&EOMONTH(DATE(2024,12,1),0)) -> 0 | AC11: 0 | AD11: =F11+H11+J11+L11+N11+P11+R11+T11+V11+X11+Z11+AB11 -> 3 | AE11: =G11+I11+K11+M11+O11+Q11+S11+U11+W11+Y11+AA11+AC11 -> 9
C12: 8 | D12: Haridwar | E12: मायापुर | F12: =COUNTIFS(Table1[(जिस फायर स्टेशन क्षेत्रार्न्तागत अग्निकाण्ड हुआ हो)],Sheet2!E12,Table1[अग्निकाण्ड का दिनांक],">="&DATE(2024,1,1), Table1[अग्निकाण्ड का दिनांक],"<="&EOMONTH(DATE(2024,1,1),0)) -> 0 | G12: 11 | H12: =COUNTIFS(Table1[(जिस फायर स्टेशन क्षेत्रार्न्तागत अग्निकाण्ड हुआ हो)],Sheet2!E12,Table1[अग्निकाण्ड का दिनांक],">="&DATE(2024,2,1), Table1[अग्निकाण्ड का दिनांक],"<="&EOMONTH(DATE(2024,2,1),0)) -> 0 | I12: 11 | J12: =COUNTIFS(Table1[(जिस फायर स्टेशन क्षेत्रार्न्तागत अग्निकाण्ड हुआ हो)],Sheet2!E12,Table1[अग्निकाण्ड का दिनांक],">="&DATE(2024,3,1), Table1[अग्निकाण्ड का दिनांक],"<="&EOMONTH(DATE(2024,3,1),0)) -> 0 | K12: 13 | L12: =COUNTIFS(Table1[(जिस फायर स्टेशन क्षेत्रार्न्तागत अग्निकाण्ड हुआ हो)],Sheet2!E12,Table1[अग्निकाण्ड का दिनांक],">="&DATE(2024,4,1), Table1[अग्निकाण्ड का दिनांक],"<="&EOMONTH(DATE(2024,4,1),0)) -> 0 | M12: 30 | N12: =COUNTIFS(Table1[(जिस फायर स्टेशन क्षेत्रार्न्तागत अग्निकाण्ड हुआ हो)],Sheet2!E12,Table1[अग्निकाण्ड का दिनांक],">="&DATE(2024,5,1), Table1[अग्निकाण्ड का दिनांक],"<="&EOMONTH(DATE(2024,5,1),0)) -> 0 | O12: 48 | P12: =COUNTIFS(Table1[(जिस फायर स्टेशन क्षेत्रार्न्तागत अग्निकाण्ड हुआ हो)],Sheet2!E12,Table1[अग्निकाण्ड का दिनांक],">="&DATE(2024,6,1), Table1[अग्निकाण्ड का दिनांक],"<="&EOMONTH(DATE(2024,6,1),0)) -> 37 | Q12: 40 | R12: =COUNTIFS(Table1[(जिस फायर स्टेशन क्षेत्रार्न्तागत अग्निकाण्ड हुआ हो)],Sheet2!E12,Table1[अग्निकाण्ड का दिनांक],">="&DATE(2024,7,1), Table1[अग्निकाण्ड का दिनांक],"<="&EOMONTH(DATE(2024,7,1),0)) -> 0 | S12: 15 | T12: =COUNTIFS(Table1[(जिस फायर स्टेशन क्षेत्रार्न्तागत अग्निकाण्ड हुआ हो)],Sheet2!E12,Table1[अग्निकाण्ड का दिनांक],">="&DATE(2024,8,1), Table1[अग्निकाण्ड का दिनांक],"<="&EOMONTH(DATE(2024,8,1),0)) -> 0 | U12: 10 | V12: =COUNTIFS(Table1[(जिस फायर स्टेशन क्षेत्रार्न्तागत अग्निकाण्ड हुआ हो)],Sheet2!E12,Table1[अग्निकाण्ड का दिनांक],">="&DATE(2024,9,1), Table1[अग्निकाण्ड का दिनांक],"<="&EOMONTH(DATE(2024,9,1),0)) -> 0 | W12: 7 | X12: =COUNTIFS(Table1[(जिस फायर स्टेशन क्षेत्रार्न्तागत अग्निकाण्ड हुआ हो)],Sheet2!E12,Table1[अग्निकाण्ड का दिनांक],">="&DATE(2024,10,1), Table1[अग्निकाण्ड का दिनांक],"<="&EOMONTH(DATE(2024,10,1),0)) -> 0 | Y12: 16 | Z12: =COUNTIFS(Table1[(जिस फायर स्टेशन क्षेत्रार्न्तागत अग्निकाण्ड हुआ हो)],Sheet2!E12,Table1[अग्निकाण्ड का दिनांक],">="&DATE(2024,11,1), Table1[अग्निकाण्ड का दिनांक],"<="&EOMONTH(DATE(2024,11,1),0)) -> 0 | AA12: 19 | AB12: =COUNTIFS(Table1[(जिस फायर स्टेशन क्षेत्रार्न्तागत अग्निकाण्ड हुआ हो)],Sheet2!E12,Table1[अग्निकाण्ड का दिनांक],">="&DATE(2024,12,1), Table1[अग्निकाण्ड का दिनांक],"<="&EOMONTH(DATE(2024,12,1),0)) -> 0 | AC12: 8 | AD12: =F12+H12+J12+L12+N12+P12+R12+T12+V12+X12+Z12+AB12 -> 37 | AE12: =G12+I12+K12+M12+O12+Q12+S12+U12+W12+Y12+AA12+AC12 -> 228
C13: 9 | E13: रूड़की | F13: =COUNTIFS(Table1[(जिस फायर स्टेशन क्षेत्रार्न्तागत अग्निकाण्ड हुआ हो)],Sheet2!E13,Table1[अग्निकाण्ड का दिनांक],">="&DATE(2024,1,1), Table1[अग्निकाण्ड का दिनांक],"<="&EOMONTH(DATE(2024,1,1),0)) -> 0 | G13: 13 | H13: =COUNTIFS(Table1[(जिस फायर स्टेशन क्षेत्रार्न्तागत अग्निकाण्ड हुआ हो)],Sheet2!E13,Table1[अग्निकाण्ड का दिनांक],">="&DATE(2024,2,1), Table1[अग्निकाण्ड का दिनांक],"<="&EOMONTH(DATE(2024,2,1),0)) -> 0 | I13: 8 | J13: =COUNTIFS(Table1[(जिस फायर स्टेशन क्षेत्रार्न्तागत अग्निकाण्ड हुआ हो)],Sheet2!E13,Table1[अग्निकाण्ड का दिनांक],">="&DATE(2024,3,1), Table1[अग्निकाण्ड का दिनांक],"<="&EOMONTH(DATE(2024,3,1),0)) -> 0 | K13: 5 | L13: =COUNTIFS(Table1[(जिस फायर स्टेशन क्षेत्रार्न्तागत अग्निकाण्ड हुआ हो)],Sheet2!E13,Table1[अग्निकाण्ड का दिनांक],">="&DATE(2024,4,1), Table1[अग्निकाण्ड का दिनांक],"<="&EOMONTH(DATE(2024,4,1),0)) -> 0 | M13: 23 | N13: =COUNTIFS(Table1[(जिस फायर स्टेशन क्षेत्रार्न्तागत अग्निकाण्ड हुआ हो)],Sheet2!E13,Table1[अग्निकाण्ड का दिनांक],">="&DATE(2024,5,1), Table1[अग्निकाण्ड का दिनांक],"<="&EOMONTH(DATE(2024,5,1),0)) -> 0 | O13: 30 | P13: =COUNTIFS(Table1[(जिस फायर स्टेशन क्षेत्रार्न्तागत अग्निकाण्ड हुआ हो)],Sheet2!E13,Table1[अग्निकाण्ड का दिनांक],">="&DATE(2024,6,1), Table1[अग्निकाण्ड का दिनांक],"<="&EOMONTH(DATE(2024,6,1),0)) -> 24 | Q13: 24 | R13: =COUNTIFS(Table1[(जिस फायर स्टेशन क्षेत्रार्न्तागत अग्निकाण्ड हुआ हो)],Sheet2!E13,Table1[अग्निकाण्ड का दिनांक],">="&DATE(2024,7,1), Table1[अग्निकाण्ड का दिनांक],"<="&EOMONTH(DATE(2024,7,1),0)) -> 0 | S13: 9 | T13: =COUNTIFS(Table1[(जिस फायर स्टेशन क्षेत्रार्न्तागत अग्निकाण्ड हुआ हो)],Sheet2!E13,Table1[अग्निकाण्ड का दिनांक],">="&DATE(2024,8,1), Table1[अग्निकाण्ड का दिनांक],"<="&EOMONTH(DATE(2024,8,1),0)) -> 0 | U13: 7 | V13: =COUNTIFS(Table1[(जिस फायर स्टेशन क्षेत्रार्न्तागत अग्निकाण्ड हुआ हो)],Sheet2!E13,Table1[अग्निकाण्ड का दिनांक],">="&DATE(2024,9,1), Table1[अग्निकाण्ड का दिनांक],"<="&EOMONTH(DATE(2024,9,1),0)) -> 0 | W13: 4 | X13: =COUNTIFS(Table1[(जिस फायर स्टेशन क्षेत्रार्न्तागत अग्निकाण्ड हुआ हो)],Sheet2!E13,Table1[अग्निकाण्ड का दिनांक],">="&DATE(2024,10,1), Table1[अग्निकाण्ड का दिनांक],"<="&EOMONTH(DATE(2024,10,1),0)) -> 0 | Y13: 5 | Z13: =COUNTIFS(Table1[(जिस फायर स्टेशन क्षेत्रार्न्तागत अग्निकाण्ड हुआ हो)],Sheet2!E13,Table1[अग्निकाण्ड का दिनांक],">="&DATE(2024,11,1), Table1[अग्निकाण्ड का दिनांक],"<="&EOMONTH(DATE(2024,11,1),0)) -> 0 | AA13: 10 | AB13: =COUNTIFS(Table1[(जिस फायर स्टेशन क्षेत्रार्न्तागत अग्निकाण्ड हुआ हो)],Sheet2!E13,Table1[अग्निकाण्ड का दिनांक],">="&DATE(2024,12,1), Table1[अग्निकाण्ड का दिनांक],"<="&EOMONTH(DATE(2024,12,1),0)) -> 0 | AC13: 19 | AD13: =F13+H13+J13+L13+N13+P13+R13+T13+V13+X13+Z13+AB13 -> 24 | AE13: =G13+I13+K13+M13+O13+Q13+S13+U13+W13+Y13+AA13+AC13 -> 157
C14: 10 | E14: लक्सर | F14: =COUNTIFS(Table1[(जिस फायर स्टेशन क्षेत्रार्न्तागत अग्निकाण्ड हुआ हो)],Sheet2!E14,Table1[अग्निकाण्ड का दिनांक],">="&DATE(2024,1,1), Table1[अग्निकाण्ड का दिनांक],"<="&EOMONTH(DATE(2024,1,1),0)) -> 0 | G14: 0 | H14: =COUNTIFS(Table1[(जिस फायर स्टेशन क्षेत्रार्न्तागत अग्निकाण्ड हुआ हो)],Sheet2!E14,Table1[अग्निकाण्ड का दिनांक],">="&DATE(2024,2,1), Table1[अग्निकाण्ड का दिनांक],"<="&EOMONTH(DATE(2024,2,1),0)) -> 0 | I14: 1 | J14: =COUNTIFS(Table1[(जिस फायर स्टेशन क्षेत्रार्न्तागत अग्निकाण्ड हुआ हो)],Sheet2!E14,Table1[अग्निकाण्ड का दिनांक],">="&DATE(2024,3,1), Table1[अग्निकाण्ड का दिनांक],"<="&EOMONTH(DATE(2024,3,1),0)) -> 0 | K14: 1 | L14: =COUNTIFS(Table1[(जिस फायर स्टेशन क्षेत्रार्न्तागत अग्निकाण्ड हुआ हो)],Sheet2!E14,Table1[अग्निकाण्ड का दिनांक],">="&DATE(2024,4,1), Table1[अग्निकाण्ड का दिनांक],"<="&EOMONTH(DATE(2024,4,1),0)) -> 0 | M14: 9 | N14: =COUNTIFS(Table1[(जिस फायर स्टेशन क्षेत्रार्न्तागत अग्निकाण्ड हुआ हो)],Sheet2!E14,Table1[अग्निकाण्ड का दिनांक],">="&DATE(2024,5,1), Table1[अग्निकाण्ड का दिनांक],"<="&EOMONTH(DATE(2024,5,1),0)) -> 0 | O14: 5 | P14: =COUNTIFS(Table1[(जिस फायर स्टेशन क्षेत्रार्न्तागत अग्निकाण्ड हुआ हो)],Sheet2!E14,Table1[अग्निकाण्ड का दिनांक],">="&DATE(2024,6,1), Table1[अग्निकाण्ड का दिनांक],"<="&EOMONTH(DATE(2024,6,1),0)) -> 8 | Q14: 8 | R14: =COUNTIFS(Table1[(जिस फायर स्टेशन क्षेत्रार्न्तागत अग्निकाण्ड हुआ हो)],Sheet2!E14,Table1[अग्निकाण्ड का दिनांक],">="&DATE(2024,7,1), Table1[अग्निकाण्ड का दिनांक],"<="&EOMONTH(DATE(2024,7,1),0)) -> 0 | S14: 0 | T14: =COUNTIFS(Table1[(जिस फायर स्टेशन क्षेत्रार्न्तागत अग्निकाण्ड हुआ हो)],Sheet2!E14,Table1[अग्निकाण्ड का दिनांक],">="&DATE(2024,8,1), Table1[अग्निकाण्ड का दिनांक],"<="&EOMONTH(DATE(2024,8,1),0)) -> 0 | U14: 0 | V14: =COUNTIFS(Table1[(जिस फायर स्टेशन क्षेत्रार्न्तागत अग्निकाण्ड हुआ हो)],Sheet2!E14,Table1[अग्निकाण्ड का दिनांक],">="&DATE(2024,9,1), Table1[अग्निकाण्ड का दिनांक],"<="&EOMONTH(DATE(2024,9,1),0)) -> 0 | W14: 1 | X14: =COUNTIFS(Table1[(जिस फायर स्टेशन क्षेत्रार्न्तागत अग्निकाण्ड हुआ हो)],Sheet2!E14,Table1[अग्निकाण्ड का दिनांक],">="&DATE(2024,10,1), Table1[अग्निकाण्ड का दिनांक],"<="&EOMONTH(DATE(2024,10,1),0)) -> 0 | Y14: 2 | Z14: =COUNTIFS(Table1[(जिस फायर स्टेशन क्षेत्रार्न्तागत अग्निकाण्ड हुआ हो)],Sheet2!E14,Table1[अग्निकाण्ड का दिनांक],">="&DATE(2024,11,1), Table1[अग्निकाण्ड का दिनांक],"<="&EOMONTH(DATE(2024,11,1),0)) -> 0 | AA14: 1 | AB14: =COUNTIFS(Table1[(जिस फायर स्टेशन क्षेत्रार्न्तागत अग्निकाण्ड हुआ हो)],Sheet2!E14,Table1[अग्निकाण्ड का दिनांक],">="&DATE(2024,12,1), Table1[अग्निकाण्ड का दिनांक],"<="&EOMONTH(DATE(2024,12,1),0)) -> 0 | AC14: 3 | AD14: =F14+H14+J14+L14+N14+P14+R14+T14+V14+X14+Z14+AB14 -> 8 | AE14: =G14+I14+K14+M14+O14+Q14+S14+U14+W14+Y14+AA14+AC14 -> 31
